<?xml version="1.0" encoding="utf-8"?>
<!-- This URDF was automatically created by SolidWorks to URDF Exporter! Originally created by Stephen Brawner (brawner@gmail.com) 
     Commit Version: 1.5.1-0-g916b5db  Build Version: 1.5.7152.31018
     For more information, please see http://wiki.ros.org/sw_urdf_exporter -->
<robot
  name="aisr">

  <gazebo>
    <plugin filename="libgazebo_ros_control.so" name="gazebo_ros_control">
      <robotNamespace>/aisr</robotNamespace>
      <robotSimType>gazebo_ros_control/DefaultRobotHWSim</robotSimType>
    </plugin>
  </gazebo>

  <gazebo reference="base_link">
    <selfCollide>false</selfCollide>
    <sensor name="base_contact_sensor" type="contact">
      <always_on>true</always_on>
      <update_rate>100.0</update_rate>
      <contact>
        <collision>base_link_collision</collision>
      </contact>
      <plugin filename="libgazebo_ros_bumper.so" name="base_gazebo_ros_bumper_controller">
        <alwaysOn>true</alwaysOn>
        <updateRate>100.0</updateRate>
        <bumperTopicName>base_bumper</bumperTopicName>
        <frameName>world</frameName>
      </plugin>
    </sensor>
  </gazebo>

  <gazebo reference="base_link">
    <material>Gazebo/Gray</material>
    <turnGravityOff>true</turnGravityOff>
  </gazebo>
  <gazebo reference="Waist_Link1">
    <material>Gazebo/Gray</material>
    <turnGravityOff>true</turnGravityOff>
  </gazebo>
  <gazebo reference="Waist_Link2">
    <material>Gazebo/Gray</material>
    <turnGravityOff>true</turnGravityOff>
  </gazebo>
  <gazebo reference="Waist_Link3">
    <material>Gazebo/Gray</material>
    <turnGravityOff>true</turnGravityOff>
  </gazebo>
  <gazebo reference="Neck_Link1">
    <material>Gazebo/Gray</material>
    <turnGravityOff>true</turnGravityOff>
  </gazebo>
  <gazebo reference="Neck_Link2">
    <material>Gazebo/Gray</material>
    <turnGravityOff>true</turnGravityOff>
  </gazebo>
  <gazebo reference="link1">
    <material>Gazebo/White</material>
    <turnGravityOff>true</turnGravityOff>
  </gazebo>
  <gazebo reference="link2">
    <material>Gazebo/White</material>
    <turnGravityOff>true</turnGravityOff>
  </gazebo>
  <gazebo reference="link3">
    <material>Gazebo/White</material>
    <turnGravityOff>true</turnGravityOff>
  </gazebo>
  <gazebo reference="link4">
    <material>Gazebo/White</material>
    <turnGravityOff>true</turnGravityOff>
  </gazebo>
  <gazebo reference="link5">
    <material>Gazebo/White</material>
    <turnGravityOff>true</turnGravityOff>
  </gazebo>
  <gazebo reference="Black_Link1">
    <material>Gazebo/Black</material>
    <turnGravityOff>true</turnGravityOff>
  </gazebo>
  <gazebo reference="Black_Link2">
    <material>Gazebo/Black</material>
    <turnGravityOff>true</turnGravityOff>
  </gazebo>
  <gazebo reference="Black_Link3">
    <material>Gazebo/Black</material>
    <turnGravityOff>true</turnGravityOff>
  </gazebo>
  <gazebo reference="Black_Link4">
    <material>Gazebo/Black</material>
    <turnGravityOff>true</turnGravityOff>
  </gazebo>
  <gazebo reference="Black_Link5">
    <material>Gazebo/Black</material>
    <turnGravityOff>true</turnGravityOff>
  </gazebo>
  <gazebo reference="Black_Link6">
    <material>Gazebo/Black</material>
    <turnGravityOff>true</turnGravityOff>
  </gazebo>
  <gazebo reference="Black_Link7">
    <material>Gazebo/Black</material>
    <turnGravityOff>true</turnGravityOff>
  </gazebo>  

  <gazebo reference="waist1_joint">
    <stopKd value="1.0"/>
    <stopKp value="1000000.0"/>
    <fudgeFactor value="0.5"/>
  </gazebo>
  <gazebo reference="waist2_joint">
    <stopKd value="1.0"/>
    <stopKp value="1000000.0"/>
    <fudgeFactor value="0.5"/>
  </gazebo>
  <gazebo reference="waist3_joint">
    <stopKd value="1.0"/>
    <stopKp value="1000000.0"/>
    <fudgeFactor value="0.5"/>
  </gazebo>
  <gazebo reference="neck1_joint">
    <stopKd value="1.0"/>
    <stopKp value="1000000.0"/>
    <fudgeFactor value="0.5"/>
  </gazebo>
  <gazebo reference="neck2_joint">
    <stopKd value="1.0"/>
    <stopKp value="1000000.0"/>
    <fudgeFactor value="0.5"/>
  </gazebo>
  <gazebo reference="joint1">
    <stopKd value="1.0"/>
    <stopKp value="1000000.0"/>
    <fudgeFactor value="0.5"/>
  </gazebo>
  <gazebo reference="joint2">
    <stopKd value="1.0"/>
    <stopKp value="1000000.0"/>
    <fudgeFactor value="0.5"/>
  </gazebo>
  <gazebo reference="joint3">
    <stopKd value="1.0"/>
    <stopKp value="1000000.0"/>
    <fudgeFactor value="0.5"/>
  </gazebo>
  <gazebo reference="joint4">
    <stopKd value="1.0"/>
    <stopKp value="1000000.0"/>
    <fudgeFactor value="0.5"/>
  </gazebo>
  <gazebo reference="joint5">
    <stopKd value="1.0"/>
    <stopKp value="1000000.0"/>
    <fudgeFactor value="0.5"/>
  </gazebo>
  <gazebo reference="black1_joint">
    <stopKd value="1.0"/>
    <stopKp value="1000000.0"/>
    <fudgeFactor value="0.5"/>
  </gazebo>
  <gazebo reference="black2_joint">
    <stopKd value="1.0"/>
    <stopKp value="1000000.0"/>
    <fudgeFactor value="0.5"/>
  </gazebo>
  <gazebo reference="black3_joint">
    <stopKd value="1.0"/>
    <stopKp value="1000000.0"/>
    <fudgeFactor value="0.5"/>
  </gazebo>
  <gazebo reference="black4_joint">
    <stopKd value="1.0"/>
    <stopKp value="1000000.0"/>
    <fudgeFactor value="0.5"/>
  </gazebo>
  <gazebo reference="black5_joint">
    <stopKd value="1.0"/>
    <stopKp value="1000000.0"/>
    <fudgeFactor value="0.5"/>
  </gazebo>
  <gazebo reference="black6_joint">
    <stopKd value="1.0"/>
    <stopKp value="1000000.0"/>
    <fudgeFactor value="0.5"/>
  </gazebo>
  <gazebo reference="black7_joint">
    <stopKd value="1.0"/>
    <stopKp value="1000000.0"/>
    <fudgeFactor value="0.5"/>
  </gazebo>

  <link name="dummy_link"/>
  <joint name="dummy_joint" type="fixed">
    <parent link="dummy_link"/>
    <child link="base_link"/>
  </joint>

  <link
    name="base_link">
    <inertial>
      <origin
        xyz="8.68737006038327E-05 0.0220759246458371 -3.60307260923483E-05"
        rpy="0 0 0" />
      <mass
        value="0.382713000180763" />
      <inertia
        ixx="0.000501239310500094"
        ixy="-6.6510878737792E-07"
        ixz="2.17235705974538E-07"
        iyy="0.00154571565906066"
        iyz="-1.70008669481295E-07"
        izz="0.00114411738992093" />
    </inertial>
    <visual>
      <origin
        xyz="0 0 0.5"
        rpy="1.5707963267949 0 -1.5707963267949" />
      <geometry>
        <mesh
          filename="package://aisr/meshes/base_link.STL" />
      </geometry>
      <material
        name="">
        <color
          rgba="0.792156862745098 0.819607843137255 0.933333333333333 1" />
      </material>
    </visual>
    <collision>
      <origin
        xyz="0 0 0.5"
        rpy="1.5707963267949 0 -1.5707963267949" />
      <geometry>
        <mesh
          filename="package://aisr/meshes/base_link.STL" />
      </geometry>
    </collision>
  </link>
  <link
    name="Waist_Link1">
    <inertial>
      <origin
        xyz="-0.000680022859402881 0.000508288562961049 0.0433092684507449"
        rpy="0 0 0" />
      <mass
        value="0.199828038005591" />
      <inertia
        ixx="0.000212533517458077"
        ixy="-7.33070976385819E-07"
        ixz="7.48907077478229E-07"
        iyy="0.00017453753802686"
        iyz="4.29948990276677E-07"
        izz="0.000198953965715132" />
    </inertial>
    <visual>
      <origin
        xyz="0 0 0"
        rpy="0 0 0" />
      <geometry>
        <mesh
          filename="package://aisr/meshes/Waist_Link1.STL" />
      </geometry>
      <material
        name="">
        <color
          rgba="0.792156862745098 0.819607843137255 0.933333333333333 1" />
      </material>
    </visual>
    <collision>
      <origin
        xyz="0 0 0"
        rpy="0 0 0" />
      <geometry>
        <mesh
          filename="package://aisr/meshes/Waist_Link1.STL" />
      </geometry>
    </collision>
  </link>
  <joint
    name="waist1_joint"
    type="revolute">
    <origin
      xyz="0 0 0.5625"
      rpy="0 0 -1.5707963267949" />
    <!-- 
    <origin
      xyz="0 0.0625 0"
      rpy="-1.5708 0 0" />
    -->
    <parent
      link="base_link" />
    <child
      link="Waist_Link1" />
    <axis
      xyz="0 0 -1" />
    <limit
      lower="-1.0"
      upper="1.0"
      effort="100.0"
      velocity="100.0" />
    <dynamics damping="0.1" friction="0.3"/>
  </joint>
  <link
    name="Waist_Link2">
    <inertial>
      <origin
        xyz="-0.00278234839054116 -0.0769133564981926 0.000480154054492906"
        rpy="0 0 0" />
      <mass
        value="0.179474506822321" />
      <inertia
        ixx="0.000391565476301261"
        ixy="-3.06217760544324E-06"
        ixz="5.57420178923787E-07"
        iyy="0.000156851856906219"
        iyz="5.97891883799137E-05"
        izz="0.000285709246916215" />
    </inertial>
    <visual>
      <origin
        xyz="0 0 0"
        rpy="0 0 0" />
      <geometry>
        <mesh
          filename="package://aisr/meshes/Waist_Link2.STL" />
      </geometry>
      <material
        name="">
        <color
          rgba="0.792156862745098 0.819607843137255 0.933333333333333 1" />
      </material>
    </visual>
    <collision>
      <origin
        xyz="0 0 0"
        rpy="0 0 0" />
      <geometry>
        <mesh
          filename="package://aisr/meshes/Waist_Link2.STL" />
      </geometry>
    </collision>
  </link>
  <joint
    name="waist2_joint"
    type="revolute">
    <origin
      xyz="0 0 0.0685"
      rpy="-1.5708 0 1.5708" />
    <parent
      link="Waist_Link1" />
    <child
      link="Waist_Link2" />
    <axis
      xyz="0 0 -1" />
    <limit
      lower="-0.5"
      upper="0.5"
      effort="100.0"
      velocity="100.0" />
    <dynamics damping="0.1" friction="0.3"/>
  </joint>
  <link
    name="Waist_Link3">
    <inertial>
      <origin
        xyz="0.0628376181458969 -0.140358964419008 0.000762862686772973"
        rpy="0 0 0" />
      <mass
        value="1.08788106388447" />
      <inertia
        ixx="0.00165410770578152"
        ixy="5.25868209942703E-05"
        ixz="2.34806564258848E-05"
        iyy="0.00159788271690302"
        iyz="6.02896699574621E-06"
        izz="0.00182039368856323" />
    </inertial>
    <visual>
      <origin
        xyz="0 0 0"
        rpy="0 0 0" />
      <geometry>
        <mesh
          filename="package://aisr/meshes/Waist_Link3.STL" />
      </geometry>
      <material
        name="">
        <color
          rgba="0.792156862745098 0.819607843137255 0.933333333333333 1" />
      </material>
    </visual>
    <collision>
      <origin
        xyz="0 0 0"
        rpy="0 0 0" />
      <geometry>
        <mesh
          filename="package://aisr/meshes/Waist_Link3.STL" />
      </geometry>
    </collision>
  </link>
  <joint
    name="waist3_joint"
    type="revolute">
    <origin
      xyz="0 -0.105 0.0007"
      rpy="0 1.5708 0" />
    <parent
      link="Waist_Link2" />
    <child
      link="Waist_Link3" />
    <axis
      xyz="0 0 1" />
    <limit
      lower="-0.5"
      upper="0.5"
      effort="100.0"
      velocity="100.0" />
    <dynamics damping="0.1" friction="0.3"/>
  </joint>
  <link
    name="Neck_Link1">
    <inertial>
      <origin
        xyz="0.0128049553987722 7.77413073152489E-14 0.0319862506332191"
        rpy="0 0 0" />
      <mass
        value="0.239221970649677" />
      <inertia
        ixx="0.000132060345588579"
        ixy="9.77292957540571E-19"
        ixz="1.61171716486014E-06"
        iyy="0.000192733563556119"
        iyz="-1.58021850608655E-17"
        izz="0.000246120579322602" />
    </inertial>
    <visual>
      <origin
        xyz="0 0 0"
        rpy="0 0 0" />
      <geometry>
        <mesh
          filename="package://aisr/meshes/Neck_Link1.STL" />
      </geometry>
      <material
        name="">
        <color
          rgba="0.792156862745098 0.819607843137255 0.933333333333333 1" />
      </material>
    </visual>
    <collision>
      <origin
        xyz="0 0 0"
        rpy="0 0 0" />
      <geometry>
        <mesh
          filename="package://aisr/meshes/Neck_Link1.STL" />
      </geometry>
    </collision>
  </link>
  <joint
    name="neck1_joint"
    type="revolute">
    <origin
      xyz="0.0005 -0.22275 -0.0002"
      rpy="1.5708 0 0" />
    <parent
      link="Waist_Link3" />
    <child
      link="Neck_Link1" />
    <axis
      xyz="0 0 -1" />
    <limit
      lower="-1.5"
      upper="1.5"
      effort="100.0"
      velocity="100.0" />
    <dynamics damping="0.1" friction="0.3"/>
  </joint>
  <link
    name="Neck_Link2">
    <inertial>
      <origin
        xyz="3.1169935989922E-11 0.0340041246895613 -0.00515653364903391"
        rpy="0 0 0" />
      <mass
        value="0.0204074561823107" />
      <inertia
        ixx="2.51279125976717E-05"
        ixy="1.12009043262145E-14"
        ixz="-1.74386514539513E-15"
        iyy="2.08081234721183E-05"
        iyz="4.6241903465433E-06"
        izz="7.36071283657067E-06" />
    </inertial>
    <visual>
      <origin
        xyz="0 0 0"
        rpy="0 0 0" />
      <geometry>
        <mesh
          filename="package://aisr/meshes/Neck_Link2.STL" />
      </geometry>
      <material
        name="">
        <color
          rgba="0.792156862745098 0.819607843137255 0.933333333333333 1" />
      </material>
    </visual>
    <collision>
      <origin
        xyz="0 0 0"
        rpy="0 0 0" />
      <geometry>
        <mesh
          filename="package://aisr/meshes/Neck_Link2.STL" />
      </geometry>
    </collision>
  </link>
  <joint
    name="neck2_joint"
    type="revolute">
    <origin
      xyz="0.0002 0 0.0415"
      rpy="1.5708 0 1.5708" />
    <parent
      link="Neck_Link1" />
    <child
      link="Neck_Link2" />
    <axis
      xyz="0 0 -1" />
    <limit
      lower="-0.5"
      upper="0.5"
      effort="100.0"
      velocity="100.0" />
    <dynamics damping="0.1" friction="0.3"/>
  </joint>
  <link
    name="link1">
    <inertial>
      <origin
        xyz="8.15757511540838E-09 -0.0245869731336436 0.0533811368110015"
        rpy="0 0 0" />
      <mass
        value="0.46221855499898" />
      <inertia
        ixx="0.00052775451208602"
        ixy="4.61279754311081E-10"
        ixz="1.53543848896261E-08"
        iyy="0.000396525476379633"
        iyz="3.45890486127802E-06"
        izz="0.000517998295789986" />
    </inertial>
    <visual>
      <origin
        xyz="0 0 0"
        rpy="0 0 0" />
      <geometry>
        <mesh
          filename="package://aisr/meshes/White_Link1.STL" />
      </geometry>
      <material
        name="">
        <color
          rgba="0.792156862745098 0.819607843137255 0.933333333333333 1" />
      </material>
    </visual>
    <collision>
      <origin
        xyz="0 0 0"
        rpy="0 0 0" />
      <geometry>
        <mesh
          filename="package://aisr/meshes/White_Link1.STL" />
      </geometry>
    </collision>
  </link>
  <joint
    name="joint1"
    type="revolute">
    <origin
      xyz="0.20962 -0.16689 -0.0002"
      rpy="1.5708 0 1.309" />
    <parent
      link="Waist_Link3" />
    <child
      link="link1" />
    <axis
      xyz="0 0 1" />
    <limit
      lower="0.0"
      upper="2.0"
      effort="100.0"
      velocity="100.0" />
    <dynamics damping="30.0" friction="0.3"/>
  </joint>
  <link
    name="link2">
    <inertial>
      <origin
        xyz="-9.43690240839956E-07 -0.0442794702919594 0.0227213080807953"
        rpy="0 0 0" />
      <mass
        value="0.103619832607522" />
      <inertia
        ixx="0.000236037136121895"
        ixy="-5.59102917229324E-09"
        ixz="1.11920025985778E-09"
        iyy="0.00014916179265272"
        iyz="-5.99562734427465E-05"
        izz="0.00015182310369525" />
    </inertial>
    <visual>
      <origin
        xyz="0 0 0"
        rpy="0 0 0" />
      <geometry>
        <mesh
          filename="package://aisr/meshes/White_Link2.STL" />
      </geometry>
      <material
        name="">
        <color
          rgba="0.792156862745098 0.819607843137255 0.933333333333333 1" />
      </material>
    </visual>
    <collision>
      <origin
        xyz="0 0 0"
        rpy="0 0 0" />
      <geometry>
        <mesh
          filename="package://aisr/meshes/White_Link2.STL" />
      </geometry>
    </collision>
  </link>
  <joint
    name="joint2"
    type="revolute">
    <origin
      xyz="0 0 0.055"
      rpy="1.5708 -1.5708 0" />
    <parent
      link="link1" />
    <child
      link="link2" />
    <axis
      xyz="0 0 1" />
    <limit
      lower="0.0"
      upper="1.5"
      effort="100.0"
      velocity="100.0" />
    <dynamics damping="10.0" friction="0.3"/>
  </joint>
  <link
    name="link3">
    <inertial>
      <origin
        xyz="0.0112747095496421 -4.73265843155667E-05 -0.106181058373573"
        rpy="0 0 0" />
      <mass
        value="0.600118848773854" />
      <inertia
        ixx="0.000504122576263287"
        ixy="-1.08214564967946E-09"
        ixz="-2.48018245384599E-07"
        iyy="0.000621971173813982"
        iyz="-8.78025620914532E-07"
        izz="0.000481195604777772" />
    </inertial>
    <visual>
      <origin
        xyz="0 0 0"
        rpy="0 0 0" />
      <geometry>
        <mesh
          filename="package://aisr/meshes/White_Link3.STL" />
      </geometry>
      <material
        name="">
        <color
          rgba="0.792156862745098 0.819607843137255 0.933333333333333 1" />
      </material>
    </visual>
    <collision>
      <origin
        xyz="0 0 0"
        rpy="0 0 0" />
      <geometry>
        <mesh
          filename="package://aisr/meshes/White_Link3.STL" />
      </geometry>
    </collision>
  </link>
  <joint
    name="joint3"
    type="revolute">
    <origin
      xyz="0 -0.08 0.0045"
      rpy="-1.5708 0 0" />
    <parent
      link="link2" />
    <child
      link="link3" />
    <axis
      xyz="0 0 -1" />
    <limit
      lower="-1.5"
      upper="1.5"
      effort="100.0"
      velocity="100.0" />
    <dynamics damping="10.0" friction="0.3"/>
  </joint>
  <link
    name="link4">
    <inertial>
      <origin
        xyz="-1.3684747878287E-08 -0.0294615833207014 0.0215098902148837"
        rpy="0 0 0" />
      <mass
        value="0.0620799654815404" />
      <inertia
        ixx="0.00013272736846259"
        ixy="-5.53095381277021E-09"
        ixz="5.65745847988659E-09"
        iyy="9.69480523042071E-05"
        iyz="-3.65974202463769E-05"
        izz="6.71102972391736E-05" />
    </inertial>
    <visual>
      <origin
        xyz="0 0 0"
        rpy="0 0 0" />
      <geometry>
        <mesh
          filename="package://aisr/meshes/White_Link4.STL" />
      </geometry>
      <material
        name="">
        <color
          rgba="0.792156862745098 0.819607843137255 0.933333333333333 1" />
      </material>
    </visual>
    <collision>
      <origin
        xyz="0 0 0"
        rpy="0 0 0" />
      <geometry>
        <mesh
          filename="package://aisr/meshes/White_Link4.STL" />
      </geometry>
    </collision>
  </link>
  <joint
    name="joint4"
    type="revolute">
    <origin
      xyz="0 0 -0.163"
      rpy="1.5708 0 1.5708" />
    <parent
      link="link3" />
    <child
      link="link4" />
    <axis
      xyz="0 0 1" />
    <limit
      lower="0.0"
      upper="2.0"
      effort="100.0"
      velocity="100.0" />
    <dynamics damping="5.0" friction="0.3"/>
  </joint>
  <link
    name="link5">
    <inertial>
      <origin
        xyz="-0.00163670637198321 -0.000337299650007622 -0.0925748094538163"
        rpy="0 0 0" />
      <mass
        value="0.439408367700066" />
      <inertia
        ixx="0.000397446548056756"
        ixy="2.86748706361497E-06"
        ixz="4.09776165865859E-07"
        iyy="0.000377647239181393"
        iyz="-1.04290172670006E-06"
        izz="0.000286315488323217" />
    </inertial>
    <visual>
      <origin
        xyz="0 0 0"
        rpy="0 0 0" />
      <geometry>
        <mesh
          filename="package://aisr/meshes/White_Link5.STL" />
      </geometry>
      <material
        name="">
        <color
          rgba="0.792156862745098 0.819607843137255 0.933333333333333 1" />
      </material>
    </visual>
    <collision>
      <origin
        xyz="0 0 0"
        rpy="0 0 0" />
      <geometry>
        <mesh
          filename="package://aisr/meshes/White_Link5.STL" />
      </geometry>
    </collision>
  </link>
  <joint
    name="joint5"
    type="revolute">
    <origin
      xyz="0 -0.06 0"
      rpy="-1.5708 -1.5708 0" />
    <parent
      link="link4" />
    <child
      link="link5" />
    <axis
      xyz="0 0 -1" />
    <limit
      lower="-1.5"
      upper="1.5"
      effort="100.0"
      velocity="100.0" />
    <dynamics damping="5.0" friction="0.3"/>
  </joint>
  
  <link name="link6" />
  <joint
    name="joint6"
    type="fixed">
    <origin
      xyz="0 0 0"
      rpy="0 0 0" />
    <parent
      link="link5" />
    <child
      link="link6" />
  </joint>
  
  <link name="link7" />
  <joint
    name="joint7"
    type="fixed">
    <origin
      xyz="0 -0.12000024 -0.325247"
      rpy="0 0 0" />
    <parent
      link="link6" />
    <child
      link="link7" />
  </joint>
  
  <link name="link_eef" />
  <joint
    name="joint_eef"
    type="fixed">
    <origin
      xyz="0 0.12000024 0.095247"
      rpy="0 0 0" />
    <parent
      link="link7" />
    <child
      link="link_eef" />
  </joint>

  <!-- Hand -->
  <joint name="white_hand" type="revolute">
    <parent link="link_eef"/>
    <child link="Link111"/>
    <!-- <origin rpy="-1.5707963267948966 1.57 0" xyz="0.01 -0.018 0.05"/> -->
    <origin rpy="-1.57 1.57 3.14" xyz="0 0 -0.045"/>
    <axis xyz="-1 0 0" />
    <limit
      lower="-3.14"
      upper="3.14"
      effort="100.0"
      velocity="100.0" />
    <dynamics damping="10.0" friction="0.3"/>
  </joint>

  <link
    name="Link111">
    <inertial>
      <origin
        xyz="0.0284046972660885 -0.00981060404810299 0.0222000386975785"
        rpy="0 0 0" />
      <mass
        value="0.22621959250221" />
      <inertia
        ixx="0.000161057742168925"
        ixy="-3.93039257205975E-06"
        ixz="-2.59552833985103E-06"
        iyy="0.000358621491446785"
        iyz="4.70540238948447E-06"
        izz="0.000257940666810454" />
    </inertial>
    <visual>
      <origin
        xyz="0 0.01 -0.0175"
        rpy="0 0 0" />
      <geometry>
        <mesh
          filename="package://aisr/meshes/r_hand/Link111.STL" />
      </geometry>
      <material
        name="">
        <color
          rgba="0.827450980392157 0.83921568627451 0.827450980392157 1" />
      </material>
    </visual>
    <collision>
      <origin
        xyz="0 0.01 -0.0175"
        rpy="0 0 0" />
      <geometry>
        <mesh
          filename="package://aisr/meshes/r_hand/Link111.STL" />
      </geometry>
    </collision>
  </link>

  <link
    name="Link1">
    <inertial>
      <origin
        xyz="0.0107729817589723 0.00213781834563882 -1.34009238303423E-07"
        rpy="0 0 0" />
      <mass
        value="0.00330620599604871" />
      <inertia
        ixx="1.55837657646135E-07"
        ixy="-3.78958094877833E-08"
        ixz="-5.07264353075226E-12"
        iyy="5.30383928507338E-07"
        iyz="-1.43523102869642E-12"
        izz="5.55164105212297E-07" />
    </inertial>
    <visual>
      <origin
        xyz="0 0.01 -0.0175"
        rpy="0 0 0" />
      <geometry>
        <mesh
          filename="package://aisr/meshes/r_hand/Link1.STL" />
      </geometry>
      <material
        name="">
        <color
          rgba="0.792156862745098 0.819607843137255 0.933333333333333 1" />
      </material>
    </visual>
    <collision>
      <origin
        xyz="0 0.01 -0.0175"
        rpy="0 0 0" />
      <geometry>
        <mesh
          filename="package://aisr/meshes/r_hand/Link1.STL" />
      </geometry>
    </collision>
  </link>
  <joint
    name="Link1"
    type="fixed">
    <origin
      xyz="0.08225 -0.0077547 -0.0040172"
      rpy="5.2178E-10 -6.245E-17 -0.14966" />
    <parent
      link="Link111" />
    <child
      link="Link1" />
    <axis
      xyz="0 0 1" />
    <limit
      lower="-1.6"
      upper="0"
      effort="1"
      velocity="100" />
  </joint>
  <link
    name="Link11">
    <inertial>
      <origin
        xyz="0.019017916514892 0.00563447754295066 1.90796464460963E-08"
        rpy="0 0 0" />
      <mass
        value="0.00453366822308025" />
      <inertia
        ixx="8.56969764665792E-08"
        ixy="-3.65502775787085E-08"
        ixz="2.02841411241907E-12"
        iyy="7.58232170757561E-07"
        iyz="6.07603435089188E-13"
        izz="7.68830975890361E-07" />
    </inertial>
    <visual>
      <origin
        xyz="0 0.01 -0.0175"
        rpy="0 0 0" />
      <geometry>
        <mesh
          filename="package://aisr/meshes/r_hand/Link11.STL" />
      </geometry>
      <material
        name="">
        <color
          rgba="1 1 1 1" />
      </material>
    </visual>
    <collision>
      <origin
        xyz="0 0.01 -0.0175"
        rpy="0 0 0" />
      <geometry>
        <mesh
          filename="package://aisr/meshes/r_hand/Link11.STL" />
      </geometry>
    </collision>
  </link>
  <joint
    name="Link11"
    type="fixed">
    <origin
      xyz="0.032132 0 0"
      rpy="-5.086E-10 -1.1653E-10 -0.22524" />
    <parent
      link="Link1" />
    <child
      link="Link11" />
    <axis
      xyz="0 0 1" />
    <limit
      lower="-1.7"
      upper="0"
      effort="1"
      velocity="100" />
  </joint>
  <link
    name="Link2">
    <inertial>
      <origin
        xyz="0.0107729781873397 0.00213783567195037 -1.14076048385314E-07"
        rpy="0 0 0" />
      <mass
        value="0.00330621565435093" />
      <inertia
        ixx="1.55837752420093E-07"
        ixy="-3.78955767951184E-08"
        ixz="-4.51740252002264E-12"
        iyy="5.30384784494186E-07"
        iyz="-1.08751322448059E-12"
        izz="5.55164342998361E-07" />
    </inertial>
    <visual>
      <origin
        xyz="0 0.01 -0.0175"
        rpy="0 0 0" />
      <geometry>
        <mesh
          filename="package://aisr/meshes/r_hand/Link2.STL" />
      </geometry>
      <material
        name="">
        <color
          rgba="0.792156862745098 0.819607843137255 0.933333333333333 1" />
      </material>
    </visual>
    <collision>
      <origin
        xyz="0 0.01 -0.0175"
        rpy="0 0 0" />
      <geometry>
        <mesh
          filename="package://aisr/meshes/r_hand/Link2.STL" />
      </geometry>
    </collision>
  </link>
  <joint
    name="Link2"
    type="fixed">
    <origin
      xyz="0.081939 -0.0077547 0.015305"
      rpy="0.0056158 -0.034452 -0.16161" />
    <parent
      link="Link111" />
    <child
      link="Link2" />
    <axis
      xyz="0 0 1" />
    <limit
      lower="-1.6"
      upper="0"
      effort="1"
      velocity="100" />
  </joint>
  <link
    name="Link22">
    <inertial>
      <origin
        xyz="0.0190179451505274 0.00563447968575673 1.97663586783137E-08"
        rpy="0 0 0" />
      <mass
        value="0.00453367017295165" />
      <inertia
        ixx="8.5696963969299E-08"
        ixy="-3.6550923619766E-08"
        ixz="1.59786933213099E-12"
        iyy="7.58233066456215E-07"
        iyz="6.81108952684927E-13"
        izz="7.68832070821997E-07" />
    </inertial>
    <visual>
      <origin
        xyz="0 0.01 -0.0175"
        rpy="0 0 0" />
      <geometry>
        <mesh
          filename="package://aisr/meshes/r_hand/Link22.STL" />
      </geometry>
      <material
        name="">
        <color
          rgba="1 1 1 1" />
      </material>
    </visual>
    <collision>
      <origin
        xyz="0 0.01 -0.0175"
        rpy="0 0 0" />
      <geometry>
        <mesh
          filename="package://aisr/meshes/r_hand/Link22.STL" />
      </geometry>
    </collision>
  </link>
  <joint
    name="Link22"
    type="fixed">
    <origin
      xyz="0.032132 0 0"
      rpy="-5.0853E-10 -1.1686E-10 -0.22588" />
    <parent
      link="Link2" />
    <child
      link="Link22" />
    <axis
      xyz="0 0 1" />
    <limit
      lower="-1.7"
      upper="0"
      effort="1"
      velocity="100" />
  </joint>
  <link
    name="Link3">
    <inertial>
      <origin
        xyz="0.0107730930654459 0.00213783260244832 -8.57328914740003E-08"
        rpy="0 0 0" />
      <mass
        value="0.0033061482917439" />
      <inertia
        ixx="1.55835970052989E-07"
        ixy="-3.78956285985318E-08"
        ixz="-3.98553229256186E-12"
        iyy="5.30379079243718E-07"
        iyz="-6.32137439938121E-13"
        izz="5.5516012983777E-07" />
    </inertial>
    <visual>
      <origin
        xyz="0 0.01 -0.0175"
        rpy="0 0 0" />
      <geometry>
        <mesh
          filename="package://aisr/meshes/r_hand/Link3.STL" />
      </geometry>
      <material
        name="">
        <color
          rgba="0.792156862745098 0.819607843137255 0.933333333333333 1" />
      </material>
    </visual>
    <collision>
      <origin
        xyz="0 0.01 -0.0175"
        rpy="0 0 0" />
      <geometry>
        <mesh
          filename="package://aisr/meshes/r_hand/Link3.STL" />
      </geometry>
    </collision>
  </link>
  <joint
    name="Link3"
    type="fixed">
    <origin
      xyz="0.080765 -0.0077547 0.034505"
      rpy="0.010408 -0.086645 -0.11971" />
    <parent
      link="Link111" />
    <child
      link="Link3" />
    <axis
      xyz="0 0 1" />
    <limit
      lower="-1.6"
      upper="0"
      effort="1"
      velocity="100" />
  </joint>
  <link
    name="Link33">
    <inertial>
      <origin
        xyz="0.01901789870244 0.00563447090562313 1.70050325960271E-08"
        rpy="0 0 0" />
      <mass
        value="0.00453366652527048" />
      <inertia
        ixx="8.56969335058099E-08"
        ixy="-3.65501984156752E-08"
        ixz="1.30339239962579E-12"
        iyy="7.58232117591424E-07"
        iyz="7.47249892192207E-13"
        izz="7.68830949295352E-07" />
    </inertial>
    <visual>
      <origin
        xyz="0 0.01 -0.0175"
        rpy="0 0 0" />
      <geometry>
        <mesh
          filename="package://aisr/meshes/r_hand/Link33.STL" />
      </geometry>
      <material
        name="">
        <color
          rgba="1 1 1 1" />
      </material>
    </visual>
    <collision>
      <origin
        xyz="0 0.01 -0.0175"
        rpy="0 0 0" />
      <geometry>
        <mesh
          filename="package://aisr/meshes/r_hand/Link33.STL" />
      </geometry>
    </collision>
  </link>
  <joint
    name="Link33"
    type="fixed">
    <origin
      xyz="0.032132 0 0"
      rpy="-5.0314E-10 -1.3824E-10 -0.26815" />
    <parent
      link="Link3" />
    <child
      link="Link33" />
    <axis
      xyz="0 0 1" />
    <limit
      lower="-1.7"
      upper="0"
      effort="1"
      velocity="100" />
  </joint>
  <link
    name="Link4">
    <inertial>
      <origin
        xyz="0.0107729931213964 0.00213782731321216 -7.95186542376647E-08"
        rpy="0 0 0" />
      <mass
        value="0.00330620800050046" />
      <inertia
        ixx="1.55837389573248E-07"
        ixy="-3.78958987950181E-08"
        ixz="-3.73884747536307E-12"
        iyy="5.30384597648764E-07"
        iyz="-3.63224479792676E-13"
        izz="5.55163794949727E-07" />
    </inertial>
    <visual>
      <origin
        xyz="0 0.01 -0.0175"
        rpy="0 0 0" />
      <geometry>
        <mesh
          filename="package://aisr/meshes/r_hand/Link4.STL" />
      </geometry>
      <material
        name="">
        <color
          rgba="0.792156862745098 0.819607843137255 0.933333333333333 1" />
      </material>
    </visual>
    <collision>
      <origin
        xyz="0 0.01 -0.0175"
        rpy="0 0 0" />
      <geometry>
        <mesh
          filename="package://aisr/meshes/r_hand/Link4.STL" />
      </geometry>
    </collision>
  </link>
  <joint
    name="Link4"
    type="fixed">
    <origin
      xyz="0.078587 -0.0077547 0.053617"
      rpy="0.022524 -0.13781 -0.16255" />
    <parent
      link="Link111" />
    <child
      link="Link4" />
    <axis
      xyz="0 0 1" />
    <limit
      lower="-1.6"
      upper="0"
      effort="1"
      velocity="100" />
  </joint>
  <link
    name="Link44">
    <inertial>
      <origin
        xyz="0.0155924853997512 0.00555619186912998 -1.21775195708468E-07"
        rpy="0 0 0" />
      <mass
        value="0.00356886192445218" />
      <inertia
        ixx="6.67767175628229E-08"
        ixy="-2.70385196277176E-08"
        ixz="-4.60032318294332E-12"
        iyy="4.33416353432936E-07"
        iyz="-1.36538016248102E-12"
        izz="4.39760949009649E-07" />
    </inertial>
    <visual>
      <origin
        xyz="0 0.01 -0.0175"
        rpy="0 0 0" />
      <geometry>
        <mesh
          filename="package://aisr/meshes/r_hand/Link44.STL" />
      </geometry>
      <material
        name="">
        <color
          rgba="1 1 1 1" />
      </material>
    </visual>
    <collision>
      <origin
        xyz="0 0.01 -0.0175"
        rpy="0 0 0" />
      <geometry>
        <mesh
          filename="package://aisr/meshes/r_hand/Link44.STL" />
      </geometry>
    </collision>
  </link>
  <joint
    name="Link44"
    type="fixed">
    <origin
      xyz="0.032132 0 0"
      rpy="-5.0686E-10 -1.2389E-10 -0.23972" />
    <parent
      link="Link4" />
    <child
      link="Link44" />
    <axis
      xyz="0 0 1" />
    <limit
      lower="-1.7"
      upper="0"
      effort="1"
      velocity="100" />
  </joint>
  <link
    name="Link5">
    <inertial>
      <origin
        xyz="-0.000668287872925624 -0.00209320996353089 0.0037633441647693"
        rpy="0 0 0" />
      <mass
        value="0.00487390663164139" />
      <inertia
        ixx="1.30408513803687E-07"
        ixy="-8.92030281859617E-09"
        ixz="-1.7660325194859E-08"
        iyy="1.70578986810531E-07"
        iyz="-1.02749399337787E-09"
        izz="2.1170907785655E-07" />
    </inertial>
    <visual>
      <origin
        xyz="0.012 0 -0.01"
        rpy="0 0 0" />
      <geometry>
        <mesh
          filename="package://aisr/meshes/r_hand/Link5.STL" />
      </geometry>
      <material
        name="">
        <color
          rgba="0.827450980392157 0.83921568627451 0.827450980392157 1" />
      </material>
    </visual>
    <collision>
      <origin
        xyz="0.012 0 -0.01"
        rpy="0 0 0" />
      <geometry>
        <mesh
          filename="package://aisr/meshes/r_hand/Link5.STL" />
      </geometry>
    </collision>
  </link>
  <joint
    name="Link5"
    type="fixed">
    <origin
      xyz="0.0089225 -0.022949 -0.00699"
      rpy="0.092365 1.1827 -1.4853" />
    <parent
      link="Link111" />
    <child
      link="Link5" />
    <axis
      xyz="0 1 0" />
    <limit
      lower="-1"
      upper="0.3"
      effort="1"
      velocity="100" />
  </joint>
  <link
    name="Link51">
    <inertial>
      <origin
        xyz="0.0261732090129406 0.00353701767650547 -1.92601341111875E-07"
        rpy="0 0 0" />
      <mass
        value="0.00652729219675812" />
      <inertia
        ixx="8.93817123585481E-07"
        ixy="6.28368840765271E-08"
        ixz="-2.00458419649248E-11"
        iyy="2.37370603240555E-06"
        iyz="-1.67466441559282E-12"
        izz="2.75021956933668E-06" />
    </inertial>
    <visual>
      <origin
        xyz="0.008 0.01 0.013"
        rpy="0 0 0" />
      <geometry>
        <mesh
          filename="package://aisr/meshes/r_hand/Link51.STL" />
      </geometry>
      <material
        name="">
        <color
          rgba="0.792156862745098 0.819607843137255 0.933333333333333 1" />
      </material>
    </visual>
    <collision>
      <origin
        xyz="0.008 0.01 0.013"
        rpy="0 0 0" />
      <geometry>
        <mesh
          filename="package://aisr/meshes/r_hand/Link51.STL" />
      </geometry>
    </collision>
  </link>
  <joint
    name="Link51"
    type="fixed">
    <origin
      xyz="0.0065 -0.0035 0.00425"
      rpy="3.1416 -5.2736E-16 0.96726" />
    <parent
      link="Link5" />
    <child
      link="Link51" />
    <axis
      xyz="0 0 -1" />
    <limit
      lower="0"
      upper="0.4"
      effort="1"
      velocity="100" />
  </joint>
  <link
    name="Link52">
    <inertial>
      <origin
        xyz="-0.007316119869056 -0.00552223433089214 2.14610152510231E-07"
        rpy="0 0 0" />
      <mass
        value="0.0022695308360543" />
      <inertia
        ixx="1.7281059843115E-07"
        ixy="4.52282139518593E-08"
        ixz="-2.88816078436063E-12"
        iyy="2.78046552011382E-07"
        iyz="7.05843881266438E-13"
        izz="2.99630657437474E-07" />
    </inertial>
    <visual>
      <origin
        xyz="0.0 -0.01 0.013"
        rpy="0 0 0" />
      <geometry>
        <mesh
          filename="package://aisr/meshes/r_hand/Link52.STL" />
      </geometry>
      <material
        name="">
        <color
          rgba="0.827450980392157 0.83921568627451 0.827450980392157 1" />
      </material>
    </visual>
    <collision>
      <origin
        xyz="0.0 -0.01 0.013"
        rpy="0 0 0" />
      <geometry>
        <mesh
          filename="package://aisr/meshes/r_hand/Link52.STL" />
      </geometry>
    </collision>
  </link>
  <joint
    name="Link52"
    type="fixed">
    <origin
      xyz="0.056001 0 0"
      rpy="0 -1.3878E-16 2.9661" />
    <parent
      link="Link51" />
    <child
      link="Link52" />
    <axis
      xyz="0 0 1" />
    <limit
      lower="-0.4"
      upper="0"
      effort="1"
      velocity="100" />
  </joint>
  <link
    name="Link53">
    <inertial>
      <origin
        xyz="-3.3937612879259E-06 0.0106230303829815 0.000584861433263272"
        rpy="0 0 0" />
      <mass
        value="0.00330869751403717" />
      <inertia
        ixx="1.96169236089202E-07"
        ixy="-1.43223823727531E-10"
        ixz="5.64113109591019E-11"
        iyy="8.67914197835909E-08"
        iyz="2.46315104630635E-08"
        izz="1.85481756939709E-07" />
    </inertial>
    <visual>
      <origin
        xyz="0.013 0 0.01"
        rpy="0 0 0" />
      <geometry>
        <mesh
          filename="package://aisr/meshes/r_hand/Link53.STL" />
      </geometry>
      <material
        name="">
        <color
          rgba="0.827450980392157 0.83921568627451 0.827450980392157 1" />
      </material>
    </visual>
    <collision>
      <origin
        xyz="0 0 0"
        rpy="0 0 0" />
      <geometry>
        <mesh
          filename="package://aisr/meshes/r_hand/Link53.STL" />
      </geometry>
    </collision>
  </link>
  <joint
    name="Link53"
    type="fixed">
    <origin
      xyz="-0.022653 0 0"
      rpy="1.7291 -1.5708 0" />
    <parent
      link="Link52" />
    <child
      link="Link53" />
    <axis
      xyz="1 0 0" />
    <limit
      lower="-1"
      upper="0"
      effort="1"
      velocity="100" />
  </joint>

  <link
    name="Black_Link1">
    <inertial>
      <origin
        xyz="-0.000147365862600168 -0.0467136348930652 -0.085610189117536"
        rpy="0 0 0" />
      <mass
        value="0.154689408708429" />
      <inertia
        ixx="0.000385987214344926"
        ixy="-3.67698000310515E-08"
        ixz="6.20067052143737E-08"
        iyy="0.000411319517078412"
        iyz="-0.000108615298758246"
        izz="0.000169047033220183" />
    </inertial>
    <visual>
      <origin
        xyz="0 0 0"
        rpy="0 0 0" />
      <geometry>
        <mesh
          filename="package://aisr/meshes/Black_Link1.STL" />
      </geometry>
      <material
        name="">
        <color
          rgba="0.792156862745098 0.819607843137255 0.933333333333333 1" />
      </material>
    </visual>
    <collision>
      <origin
        xyz="0 0 0"
        rpy="0 0 0" />
      <geometry>
        <mesh
          filename="package://aisr/meshes/Black_Link1.STL" />
      </geometry>
    </collision>
  </link>
  <joint
    name="black1_joint"
    type="revolute">
    <origin
      xyz="-0.13313 -0.14666 -0.0002"
      rpy="-1.5708 0 -1.309" />
    <parent
      link="Waist_Link3" />
    <child
      link="Black_Link1" />
    <axis
      xyz="0 0 -1" />
    <limit
      lower="-2.0"
      upper="0.0"
      effort="100.0"
      velocity="100.0" />
    <dynamics damping="30.0" friction="0.3"/>
  </joint>
  <link
    name="Black_Link2">
    <inertial>
      <origin
        xyz="0.000652695129614911 -0.0653915519829706 -0.00523905330756468"
        rpy="0 0 0" />
      <mass
        value="0.158018881147199" />
      <inertia
        ixx="0.000181430744978423"
        ixy="1.85115107021316E-06"
        ixz="3.19061886301373E-07"
        iyy="0.00021950347348579"
        iyz="2.45726657891494E-05"
        izz="0.000171999160864318" />
    </inertial>
    <visual>
      <origin
        xyz="0 0 0"
        rpy="0 0 0" />
      <geometry>
        <mesh
          filename="package://aisr/meshes/Black_Link2.STL" />
      </geometry>
      <material
        name="">
        <color
          rgba="0.792156862745098 0.819607843137255 0.933333333333333 1" />
      </material>
    </visual>
    <collision>
      <origin
        xyz="0 0 0"
        rpy="0 0 0" />
      <geometry>
        <mesh
          filename="package://aisr/meshes/Black_Link2.STL" />
      </geometry>
    </collision>
  </link>
  <joint
    name="black2_joint"
    type="revolute">
    <origin
      xyz="0 0 -0.1165"
      rpy="-1.5708 -1.309 0" />
    <parent
      link="Black_Link1" />
    <child
      link="Black_Link2" />
    <axis
      xyz="0 0 -1" />
    <limit
      lower="0.0"
      upper="1.5"
      effort="100.0"
      velocity="100.0" />
    <dynamics damping="20.0" friction="0.3"/>
  </joint>
  <link
    name="black_Link3">
    <inertial>
      <origin
        xyz="0.0029020738839261 -0.00019495225768067 -0.0820858347611841"
        rpy="0 0 0" />
      <mass
        value="0.261626822815551" />
      <inertia
        ixx="0.000350258511253729"
        ixy="-2.76031600143513E-07"
        ixz="-1.90354331428809E-06"
        iyy="0.000234259918328669"
        iyz="-1.25284016414465E-07"
        izz="0.000180305938628177" />
    </inertial>
    <visual>
      <origin
        xyz="0 0 0"
        rpy="0 0 0" />
      <geometry>
        <mesh
          filename="package://aisr/meshes/black_Link3.STL" />
      </geometry>
      <material
        name="">
        <color
          rgba="0.792156862745098 0.819607843137255 0.933333333333333 1" />
      </material>      
    </visual>
    <collision>
      <origin
        xyz="0 0 0"
        rpy="0 0 0" />
      <geometry>
        <mesh
          filename="package://aisr/meshes/black_Link3.STL" />
      </geometry>
    </collision>
  </link>
  <joint
    name="black3_joint"
    type="revolute">
    <origin
      xyz="0 -0.11415 -0.0002"
      rpy="-1.5708 0 0" />
    <parent
      link="Black_Link2" />
    <child
      link="black_Link3" />
    <axis
      xyz="0 0 -1" />
    <limit
      lower="-1.5"
      upper="1.5"
      effort="100.0"
      velocity="100.0" />
    <dynamics damping="10.0" friction="0.3"/>
  </joint>
  <link
    name="Black_Link4">
    <inertial>
      <origin
        xyz="5.65242483704733E-05 -0.0501339831519513 0.0049715865659172"
        rpy="0 0 0" />
      <mass
        value="0.146566591735319" />
      <inertia
        ixx="7.49600865131283E-05"
        ixy="1.73862786044255E-07"
        ixz="3.34708632631287E-07"
        iyy="8.17474786777777E-05"
        iyz="3.55090309901845E-06"
        izz="8.24113917019771E-05" />
    </inertial>
    <visual>
      <origin
        xyz="0 0 0"
        rpy="0 0 0" />
      <geometry>
        <mesh
          filename="package://aisr/meshes/Black_Link4.STL" />
      </geometry>
      <material
        name="">
        <color
          rgba="0.792156862745098 0.819607843137255 0.933333333333333 1" />
      </material>
    </visual>
    <collision>
      <origin
        xyz="0 0 0"
        rpy="0 0 0" />
      <geometry>
        <mesh
          filename="package://aisr/meshes/Black_Link4.STL" />
      </geometry>
    </collision>
  </link>
  <joint
    name="black4_joint"
    type="revolute">
    <origin
      xyz="0 0 -0.1482"
      rpy="1.5708 0 1.5708" />
    <parent
      link="black_Link3" />
    <child
      link="Black_Link4" />
    <axis
      xyz="0 0 1" />
    <limit
      lower="0.0"
      upper="2.0"
      effort="100.0"
      velocity="100.0" />
    <dynamics damping="10.0" friction="0.3"/>
  </joint>
  <link
    name="Black_Link5">
    <inertial>
      <origin
        xyz="8.04192166260209E-05 0.00396894443088205 -0.0417414760124886"
        rpy="0 0 0" />
      <mass
        value="0.113603854400732" />
      <inertia
        ixx="4.91983214083984E-05"
        ixy="1.45915336633566E-07"
        ixz="-1.17278437826805E-07"
        iyy="8.1393838375801E-05"
        iyz="-6.17697102728606E-07"
        izz="5.71114235989413E-05" />
    </inertial>
    <visual>
      <origin
        xyz="0 0 0"
        rpy="0 0 0" />
      <geometry>
        <mesh
          filename="package://aisr/meshes/Black_Link5.STL" />
      </geometry>
      <material
        name="">
        <color
          rgba="0.792156862745098 0.819607843137255 0.933333333333333 1" />
      </material>
    </visual>
    <collision>
      <origin
        xyz="0 0 0"
        rpy="0 0 0" />
      <geometry>
        <mesh
          filename="package://aisr/meshes/Black_Link5.STL" />
      </geometry>
    </collision>
  </link>
  <joint
    name="black5_joint"
    type="revolute">
    <origin
      xyz="0 -0.10775 0"
      rpy="-1.5708 -1.5708 0" />
    <parent
      link="Black_Link4" />
    <child
      link="Black_Link5" />
    <axis
      xyz="0 0 -1" />
    <limit
      lower="-1.5"
      upper="1.5"
      effort="100.0"
      velocity="100.0" />
    <dynamics damping="1.0" friction="0.3"/>
  </joint>
  <link
    name="Black_Link6">
    <inertial>
      <origin
        xyz="-0.00050879569890927 -0.0637453259758228 0.000446218075178181"
        rpy="0 0 0" />
      <mass
        value="0.136719505415783" />
      <inertia
        ixx="0.000111041834294903"
        ixy="-1.48548837840546E-06"
        ixz="-5.17101846495441E-07"
        iyy="6.9415324357276E-05"
        iyz="-7.9392701982966E-06"
        izz="6.82823374161429E-05" />
    </inertial>
    <visual>
      <origin
        xyz="0 0 0"
        rpy="0 0 0" />
      <geometry>
        <mesh
          filename="package://aisr/meshes/Black_Link6.STL" />
      </geometry>
      <material
        name="">
        <color
          rgba="0.792156862745098 0.819607843137255 0.933333333333333 1" />
      </material>
    </visual>
    <collision>
      <origin
        xyz="0 0 0"
        rpy="0 0 0" />
      <geometry>
        <mesh
          filename="package://aisr/meshes/Black_Link6.STL" />
      </geometry>
    </collision>
  </link>
  <joint
    name="black6_joint"
    type="revolute">
    <origin
      xyz="0 0 -0.0481"
      rpy="1.5708 0 0" />
    <parent
      link="Black_Link5" />
    <child
      link="Black_Link6" />
    <axis
      xyz="0 0 1" />
    <limit
      lower="-1.5"
      upper="1.5"
      effort="100.0"
      velocity="100.0" />
    <dynamics damping="0.1" friction="0.3"/>
  </joint>
  <link
    name="Black_Link7">
    <inertial>
      <origin
        xyz="0.000279675154683716 -0.0305880858388763 -0.000827498473390614"
        rpy="0 0 0" />
      <mass
        value="0.0255440416704045" />
      <inertia
        ixx="1.88403328326683E-05"
        ixy="7.90896979203136E-08"
        ixz="4.44043087335717E-08"
        iyy="8.43417962576022E-06"
        iyz="1.45351145787414E-06"
        izz="1.66232632442622E-05" />
    </inertial>
    <visual>
      <origin
        xyz="0 0 0"
        rpy="0 0 0" />
      <geometry>
        <mesh
          filename="package://aisr/meshes/Black_Link7.STL" />
      </geometry>
      <material
        name="">
        <color
          rgba="0.792156862745098 0.819607843137255 0.933333333333333 1" />
      </material>
    </visual>
    <collision>
      <origin
        xyz="0 0 0"
        rpy="0 0 0" />
      <geometry>
        <mesh
          filename="package://aisr/meshes/Black_Link7.STL" />
      </geometry>
    </collision>
  </link>
  <joint
    name="black7_joint"
    type="revolute">
    <origin
      xyz="0 -0.078 0"
      rpy="0 1.5708 0" />
    <parent
      link="Black_Link6" />
    <child
      link="Black_Link7" />
    <axis
      xyz="0 0 -1" />
    <limit
      lower="-1.5"
      upper="1.5"
      effort="100.0"
      velocity="100.0" />
    <dynamics damping="0.1" friction="0.3"/>
  </joint>

  <transmission name="waist1_trans"> 
    <type>transmission_interface/SimpleTransmission</type>
    <joint name="waist1_joint">
      <hardwareInterface>hardware_interface/PositionJointInterface</hardwareInterface>
    </joint>
    <actuator name="waist1_motor">
      <hardwareInterface>hardware_interface/PositionJointInterface</hardwareInterface>
      <mechanicalReduction>32.6</mechanicalReduction>
    </actuator>
  </transmission>

  <transmission name="waist2_trans"> 
    <type>transmission_interface/SimpleTransmission</type>
    <joint name="waist2_joint">
      <hardwareInterface>hardware_interface/PositionJointInterface</hardwareInterface>
    </joint>
    <actuator name="waist2_motor">
      <hardwareInterface>hardware_interface/PositionJointInterface</hardwareInterface>
      <mechanicalReduction>32.6</mechanicalReduction>
    </actuator>
  </transmission>

  <transmission name="waist3_trans"> 
    <type>transmission_interface/SimpleTransmission</type>
    <joint name="waist3_joint">
      <hardwareInterface>hardware_interface/PositionJointInterface</hardwareInterface>
    </joint>
    <actuator name="waist3_motor">
      <hardwareInterface>hardware_interface/PositionJointInterface</hardwareInterface>
      <mechanicalReduction>32.6</mechanicalReduction>
    </actuator>
  </transmission>

  <transmission name="neck1_trans"> 
    <type>transmission_interface/SimpleTransmission</type>
    <joint name="neck1_joint">
      <hardwareInterface>hardware_interface/PositionJointInterface</hardwareInterface>
    </joint>
    <actuator name="neck1_motor">
      <hardwareInterface>hardware_interface/PositionJointInterface</hardwareInterface>
      <mechanicalReduction>32.6</mechanicalReduction>
    </actuator>
  </transmission>

  <transmission name="neck2_trans"> 
    <type>transmission_interface/SimpleTransmission</type>
    <joint name="neck2_joint">
      <hardwareInterface>hardware_interface/PositionJointInterface</hardwareInterface>
    </joint>
    <actuator name="neck2_motor">
      <hardwareInterface>hardware_interface/PositionJointInterface</hardwareInterface>
      <mechanicalReduction>32.6</mechanicalReduction>
    </actuator>
  </transmission>

  <transmission name="white1_trans"> 
    <type>transmission_interface/SimpleTransmission</type>
    <joint name="joint1">
      <hardwareInterface>hardware_interface/PositionJointInterface</hardwareInterface>
    </joint>
    <actuator name="white1_motor">
      <hardwareInterface>hardware_interface/PositionJointInterface</hardwareInterface>
      <mechanicalReduction>32.6</mechanicalReduction>
    </actuator>
  </transmission>

  <transmission name="white2_trans"> 
    <type>transmission_interface/SimpleTransmission</type>
    <joint name="joint2">
      <hardwareInterface>hardware_interface/PositionJointInterface</hardwareInterface>
    </joint>
    <actuator name="white2_motor">
      <hardwareInterface>hardware_interface/PositionJointInterface</hardwareInterface>
      <mechanicalReduction>32.6</mechanicalReduction>
    </actuator>
  </transmission>

  <transmission name="white3_trans"> 
    <type>transmission_interface/SimpleTransmission</type>
    <joint name="joint3">
      <hardwareInterface>hardware_interface/PositionJointInterface</hardwareInterface>
    </joint>
    <actuator name="white3_motor">
      <hardwareInterface>hardware_interface/PositionJointInterface</hardwareInterface>
      <mechanicalReduction>32.6</mechanicalReduction>
    </actuator>
  </transmission>

  <transmission name="white4_trans"> 
    <type>transmission_interface/SimpleTransmission</type>
    <joint name="joint4">
      <hardwareInterface>hardware_interface/PositionJointInterface</hardwareInterface>
    </joint>
    <actuator name="white4_motor">
      <hardwareInterface>hardware_interface/PositionJointInterface</hardwareInterface>
      <mechanicalReduction>32.6</mechanicalReduction>
    </actuator>
  </transmission>

  <transmission name="white5_trans"> 
    <type>transmission_interface/SimpleTransmission</type>
    <joint name="joint5">
      <hardwareInterface>hardware_interface/PositionJointInterface</hardwareInterface>
    </joint>
    <actuator name="white5_motor">
      <hardwareInterface>hardware_interface/PositionJointInterface</hardwareInterface>
      <mechanicalReduction>32.6</mechanicalReduction>
    </actuator>
  </transmission>

  <transmission name="black1_trans"> 
    <type>transmission_interface/SimpleTransmission</type>
    <joint name="black1_joint">
      <hardwareInterface>hardware_interface/PositionJointInterface</hardwareInterface>
    </joint>
    <actuator name="black1_motor">
      <hardwareInterface>hardware_interface/PositionJointInterface</hardwareInterface>
      <mechanicalReduction>32.6</mechanicalReduction>
    </actuator>
  </transmission>

  <transmission name="black2_trans"> 
    <type>transmission_interface/SimpleTransmission</type>
    <joint name="black2_joint">
      <hardwareInterface>hardware_interface/PositionJointInterface</hardwareInterface>
    </joint>
    <actuator name="black2_motor">
      <hardwareInterface>hardware_interface/PositionJointInterface</hardwareInterface>
      <mechanicalReduction>32.6</mechanicalReduction>
    </actuator>
  </transmission>

  <transmission name="black3_trans"> 
    <type>transmission_interface/SimpleTransmission</type>
    <joint name="black3_joint">
      <hardwareInterface>hardware_interface/PositionJointInterface</hardwareInterface>
    </joint>
    <actuator name="black3_motor">
      <hardwareInterface>hardware_interface/PositionJointInterface</hardwareInterface>
      <mechanicalReduction>32.6</mechanicalReduction>
    </actuator>
  </transmission>

  <transmission name="black4_trans"> 
    <type>transmission_interface/SimpleTransmission</type>
    <joint name="black4_joint">
      <hardwareInterface>hardware_interface/PositionJointInterface</hardwareInterface>
    </joint>
    <actuator name="black4_motor">
      <hardwareInterface>hardware_interface/PositionJointInterface</hardwareInterface>
      <mechanicalReduction>32.6</mechanicalReduction>
    </actuator>
  </transmission>

  <transmission name="black5_trans"> 
    <type>transmission_interface/SimpleTransmission</type>
    <joint name="black5_joint">
      <hardwareInterface>hardware_interface/PositionJointInterface</hardwareInterface>
    </joint>
    <actuator name="black5_motor">
      <hardwareInterface>hardware_interface/PositionJointInterface</hardwareInterface>
      <mechanicalReduction>32.6</mechanicalReduction>
    </actuator>
  </transmission>

  <transmission name="black6_trans"> 
    <type>transmission_interface/SimpleTransmission</type>
    <joint name="black6_joint">
      <hardwareInterface>hardware_interface/PositionJointInterface</hardwareInterface>
    </joint>
    <actuator name="black6_motor">
      <hardwareInterface>hardware_interface/PositionJointInterface</hardwareInterface>
      <mechanicalReduction>32.6</mechanicalReduction>
    </actuator>
  </transmission>

  <transmission name="black7_trans"> 
    <type>transmission_interface/SimpleTransmission</type>
    <joint name="black7_joint">
      <hardwareInterface>hardware_interface/PositionJointInterface</hardwareInterface>
    </joint>
    <actuator name="black7_moter">
      <hardwareInterface>hardware_interface/PositionJointInterface</hardwareInterface>
      <mechanicalReduction>32.6</mechanicalReduction>
    </actuator>
  </transmission>

</robot>
