<?xml version="1.0" ?>
<!-- =================================================================================== -->
<!-- |    This document was autogenerated by xacro from /opt/ros/kinetic/share/moveit_resources/panda_description/urdf/panda.urdf | -->
<!-- |    EDITING THIS FILE BY HAND IS NOT RECOMMENDED                                 | -->
<!-- =================================================================================== -->
<robot name="panda" xmlns:xacro="http://www.ros.org/wiki/xacro">
 
 
  <link name="dummy_link"/>
  <joint name="fixed" type="fixed">
    <parent link="dummy_link"/>
    <child link="panda_link0"/>
    <origin
      xyz="0 0 0"
      rpy="0 0 1.5708" />
  </joint>
  
  <link
    name="panda_link0">
    <inertial>
      <origin
        xyz="0.0012275 0.010486 0.36069"
        rpy="0 0 0" />
      <mass
        value="38.318" />
      <inertia
        ixx="0.30021"
        ixy="-0.0038491"
        ixz="6.5349E-05"
        iyy="0.49607"
        iyz="-0.00075005"
        izz="0.55425" />
    </inertial>
    <visual>
      <origin
        xyz="0 0 0"
        rpy="0 0 0" />
      <geometry>
        <mesh
          filename="package://moveit_resources_panda_description/meshes/base_link.STL" />
      </geometry>
      <material
        name="">
        <color
          rgba="0.79216 0.81961 0.93333 1" />
      </material>
    </visual>
    <collision>
      <origin
        xyz="0 0 0"
        rpy="0 0 0" />
      <geometry>
        <mesh
          filename="package://moveit_resources_panda_description/meshes/base_link.STL" />
      </geometry>
    </collision>
  </link>
  <link
    name="panda_link1">
    <inertial>
      <origin
        xyz="1.3185E-08 -0.024587 0.053381"
        rpy="0 0 0" />
      <mass
        value="0.46222" />
      <inertia
        ixx="0.00052775"
        ixy="5.4121E-10"
        ixz="1.53E-08"
        iyy="0.00039653"
        iyz="3.4588E-06"
        izz="0.000518" />
    </inertial>
    <visual>
      <origin
        xyz="0 0 0"
        rpy="0 0 0" />
      <geometry>
        <mesh
          filename="package://moveit_resources_panda_description/meshes/white_link1.STL" />
      </geometry>
      <material
        name="">
        <color
          rgba="0.79216 0.81961 0.93333 1" />
      </material>
    </visual>
    <collision>
      <origin
        xyz="0 0 0"
        rpy="0 0 0" />
      <geometry>
        <mesh
          filename="package://moveit_resources_panda_description/meshes/white_link1.STL" />
      </geometry>
    </collision>
  </link>
  <joint
    name="panda_joint1"
    type="revolute">
    <origin
      xyz="-0.209119220989971 0 1.17089202757203"
      rpy="0 -1.30899693899575 0" />
    <parent
      link="panda_link0" />
    <child
      link="panda_link1" />
    <axis
      xyz="0 0 1" />
    <limit
      lower="-1.57"
      upper="2.3"
      effort="0"
      velocity="0" />
  </joint>
  <link
    name="panda_link2">
    <inertial>
      <origin
        xyz="-0.00928787823353383 0.0432944256908163 -0.0227212914243321"
        rpy="0 0 0" />
      <mass
        value="0.10361980808425" />
      <inertia
        ixx="0.00023221319029822"
        ixy="1.78206200084059E-05"
        ixz="1.25738365505724E-05"
        iyy="0.000152985602235276"
        iyz="-5.86229272307586E-05"
        izz="0.000151822930596877" />
    </inertial>
    <visual>
      <origin
        xyz="0 0 0"
        rpy="0 0 0" />
      <geometry>
        <mesh
          filename="package://moveit_resources_panda_description/meshes/white_link2.STL" />
      </geometry>
      <material
        name="">
        <color
          rgba="0.792156862745098 0.819607843137255 0.933333333333333 1" />
      </material>
    </visual>
    <collision>
      <origin
        xyz="0 0 0"
        rpy="0 0 0" />
      <geometry>
        <mesh
          filename="package://moveit_resources_panda_description/meshes/white_link2.STL" />
      </geometry>
    </collision>
  </link>
  <joint
    name="panda_joint2"
    type="revolute">
    <origin
      xyz="0 0 0.0549999999999993"
      rpy="-1.5707963267949 1.30899693899575 0" />
    <parent
      link="panda_link1" />
    <child
      link="panda_link2" />
    <axis
      xyz="0 0 -1" />
    <limit
      lower="-2.0"
      upper="0.15"
      effort="0"
      velocity="0" />
  </joint>
  <link
    name="panda_link3">
    <inertial>
      <origin
        xyz="-4.7316E-05 -0.011275 -0.10618"
        rpy="0 0 0" />
      <mass
        value="0.60012" />
      <inertia
        ixx="0.00062197"
        ixy="1.1122E-09"
        ixz="-8.7805E-07"
        iyy="0.00050412"
        iyz="2.4775E-07"
        izz="0.0004812" />
    </inertial>
    <visual>
      <origin
        xyz="0 0 0"
        rpy="0 0 0" />
      <geometry>
        <mesh
          filename="package://moveit_resources_panda_description/meshes/white_link3.STL" />
      </geometry>
      <material
        name="">
        <color
          rgba="0.79216 0.81961 0.93333 1" />
      </material>
    </visual>
    <collision>
      <origin
        xyz="0 0 0"
        rpy="0 0 0" />
      <geometry>
        <mesh
          filename="package://moveit_resources_panda_description/meshes/white_link3.STL" />
      </geometry>
    </collision>
  </link>
  <joint
    name="panda_joint3"
    type="revolute">
    <origin
      xyz="-0.0167788293984912 0.0782206550982036 -0.00450000000001032"
      rpy="1.57079632679491 1.56 0.211304299584282" />
    <parent
      link="panda_link2" />
    <child
      link="panda_link3" />
    <axis
      xyz="0 0 -1" />
    <limit
      lower="-1.57"
      upper="1.0"
      effort="0"
      velocity="0" />
  </joint>
  <link
    name="panda_link4">
    <inertial>
      <origin
        xyz="0.00617917033195248 -0.0288063080433174 -0.0215098884378817"
        rpy="0 0 0" />
      <mass
        value="0.0620799688774293" />
      <inertia
        ixx="0.00013115115732738"
        ixy="7.34226597375444E-06"
        ixz="-7.67017958449621E-06"
        iyy="9.85241823427642E-05"
        iyz="3.57845945382075E-05"
        izz="6.71102640248013E-05" />
    </inertial>
    <visual>
      <origin
        xyz="0 0 0"
        rpy="0 0 0" />
      <geometry>
        <mesh
          filename="package://moveit_resources_panda_description/meshes/white_link4.STL" />
      </geometry>
      <material
        name="">
        <color
          rgba="0.792156862745098 0.819607843137255 0.933333333333333 1" />
      </material>
    </visual>
    <collision>
      <origin
        xyz="0 0 0"
        rpy="0 0 0" />
      <geometry>
        <mesh
          filename="package://moveit_resources_panda_description/meshes/white_link4.STL" />
      </geometry>
    </collision>
  </link>
  <joint
    name="panda_joint4"
    type="revolute">
    <origin
      xyz="0 0 -0.163"
      rpy="1.57079632679491 0.211304299584282 3.14159265358956" />
    <parent
      link="panda_link3" />
    <child
      link="panda_link4" />
    <axis
      xyz="0 0 1" />
    <limit
      lower="-2.0"
      upper="0.0"
      effort="0"
      velocity="0" />
  </joint>
  <link
    name="panda_link5">
    <inertial>
      <origin
        xyz="-0.000188265942452026 0.00166043716051721 -0.0925746485298249"
        rpy="0 0 0" />
      <mass
        value="0.439407691305706" />
      <inertia
        ixx="0.000377291678402614"
        ixy="-1.04184251001465E-06"
        ixz="-1.07560528160567E-06"
        iyy="0.000397799259735699"
        iyz="-3.14054896887713E-07"
        izz="0.000286315477112447" />
    </inertial>
    <visual>
      <origin
        xyz="0 0 0"
        rpy="0 0 0" />
      <geometry>
        <mesh
          filename="package://moveit_resources_panda_description/meshes/white_link5.STL" />
      </geometry>
      <material
        name="">
        <color
          rgba="0.792156862745098 0.819607843137255 0.933333333333333 1" />
      </material>
    </visual>
    <collision>
      <origin
        xyz="0 0 0"
        rpy="0 0 0" />
      <geometry>
        <mesh
          filename="package://moveit_resources_panda_description/meshes/white_link5.STL" />
      </geometry>
    </collision>
  </link>
  <joint
    name="panda_joint5"
    type="revolute">
    <origin
      xyz="0.0125841220490822 -0.0586654913237358 0"
      rpy="1.57079632679491 -1.51 -2.93028835400551" />
    <parent
      link="panda_link4" />
    <child
      link="panda_link5" />
    <axis
      xyz="0 0 1" />
    <limit
      lower="-3.0"
      upper="3.0"
      effort="0"
      velocity="0" />
  </joint>

  <link name="panda_link6" />
  <joint
    name="panda_joint6"
    type="fixed">
    <origin
      xyz="0 0 0"
      rpy="0 0 0" />
    <parent
      link="panda_link5" />
    <child
      link="panda_link6" />
  </joint>
  
  <link name="panda_link7" />
  <joint
    name="panda_joint7"
    type="fixed">
    <origin
      xyz="0 0 0"
      rpy="0 0 0" />
    <parent
      link="panda_link6" />
    <child
      link="panda_link7" />
  </joint>
  
  <link name="panda_link8" />
  <joint
    name="panda_joint8"
    type="fixed">
    <origin
      xyz="0.03 0.075 -0.373"
      rpy="0 0 0" />
    <parent
      link="panda_link7" />
    <child
      link="panda_link8" />
  </joint>





  <!-- 手 -->
  <joint name="white_hand" type="fixed">
    <parent link="panda_link7"/>
    <child link="panda_hand"/>
    <!-- <origin rpy="-1.5707963267948966 1.57 0" xyz="0.01 -0.018 0.05"/> -->
    <origin rpy="-1.5707963267948966 1.57 0" xyz="-0.01 -0.02 -0.28"/>
  </joint>

  <link
    name="panda_hand">
    <inertial>
      <origin
        xyz="0.0284046972660885 -0.00981060404810299 0.0222000386975785"
        rpy="0 0 0" />
      <mass
        value="0.22621959250221" />
      <inertia
        ixx="0.000161057742168925"
        ixy="-3.93039257205975E-06"
        ixz="-2.59552833985103E-06"
        iyy="0.000358621491446785"
        iyz="4.70540238948447E-06"
        izz="0.000257940666810454" />
    </inertial>
    <visual>
      <origin
        xyz="0 0 0"
        rpy="0 0 0" />
      <geometry>
        <mesh
          filename="package://moveit_resources_panda_description/meshes/r_hand/Link111.STL" />
      </geometry>
      <material
        name="">
        <color
          rgba="0.827450980392157 0.83921568627451 0.827450980392157 1" />
      </material>
    </visual>
    <collision>
      <origin
        xyz="0 0 0"
        rpy="0 0 0" />
      <geometry>
        <mesh
          filename="package://moveit_resources_panda_description/meshes/r_hand/Link111.STL" />
      </geometry>
    </collision>
  </link>
  <link
    name="panda_leftfinger">
    <inertial>
      <origin
        xyz="0.0107729817589723 0.00213781834563882 -1.34009238303423E-07"
        rpy="0 0 0" />
      <mass
        value="0.00330620599604871" />
      <inertia
        ixx="1.55837657646135E-07"
        ixy="-3.78958094877833E-08"
        ixz="-5.07264353075226E-12"
        iyy="5.30383928507338E-07"
        iyz="-1.43523102869642E-12"
        izz="5.55164105212297E-07" />
    </inertial>
    <visual>
      <origin
        xyz="0 0 0"
        rpy="0 0 0" />
      <geometry>
        <mesh
          filename="package://moveit_resources_panda_description/meshes/r_hand/Link1.STL" />
      </geometry>
      <material
        name="">
        <color
          rgba="0.792156862745098 0.819607843137255 0.933333333333333 1" />
      </material>
    </visual>
    <collision>
      <origin
        xyz="0 0 0"
        rpy="0 0 0" />
      <geometry>
        <mesh
          filename="package://moveit_resources_panda_description/meshes/r_hand/Link1.STL" />
      </geometry>
    </collision>
  </link>
  <joint
    name="panda_finger_joint1"
    type="revolute">
    <origin
      xyz="0.08225 -0.0077547 -0.0040172"
      rpy="5.2178E-10 -6.245E-17 -0.14966" />
    <parent
      link="panda_hand" />
    <child
      link="panda_leftfinger" />
    <axis
      xyz="0 0 1" />
    <limit
      lower="-1.6"
      upper="0"
      effort="1"
      velocity="1" />
  </joint>
  <link
    name="Link11">
    <inertial>
      <origin
        xyz="0.019017916514892 0.00563447754295066 1.90796464460963E-08"
        rpy="0 0 0" />
      <mass
        value="0.00453366822308025" />
      <inertia
        ixx="8.56969764665792E-08"
        ixy="-3.65502775787085E-08"
        ixz="2.02841411241907E-12"
        iyy="7.58232170757561E-07"
        iyz="6.07603435089188E-13"
        izz="7.68830975890361E-07" />
    </inertial>
    <visual>
      <origin
        xyz="0 0 0"
        rpy="0 0 0" />
      <geometry>
        <mesh
          filename="package://moveit_resources_panda_description/meshes/r_hand/Link11.STL" />
      </geometry>
      <material
        name="">
        <color
          rgba="1 1 1 1" />
      </material>
    </visual>
    <collision>
      <origin
        xyz="0 0 0"
        rpy="0 0 0" />
      <geometry>
        <mesh
          filename="package://moveit_resources_panda_description/meshes/r_hand/Link11.STL" />
      </geometry>
    </collision>
  </link>
  <joint
    name="Link11"
    type="revolute">
    <origin
      xyz="0.032132 0 0"
      rpy="-5.086E-10 -1.1653E-10 -0.22524" />
    <parent
      link="panda_leftfinger" />
    <child
      link="Link11" />
    <axis
      xyz="0 0 1" />
    <limit
      lower="-1.7"
      upper="0"
      effort="1"
      velocity="1" />
  </joint>
  <link
    name="panda_rightfinger">
    <inertial>
      <origin
        xyz="0.0107729781873397 0.00213783567195037 -1.14076048385314E-07"
        rpy="0 0 0" />
      <mass
        value="0.00330621565435093" />
      <inertia
        ixx="1.55837752420093E-07"
        ixy="-3.78955767951184E-08"
        ixz="-4.51740252002264E-12"
        iyy="5.30384784494186E-07"
        iyz="-1.08751322448059E-12"
        izz="5.55164342998361E-07" />
    </inertial>
    <visual>
      <origin
        xyz="0 0 0"
        rpy="0 0 0" />
      <geometry>
        <mesh
          filename="package://moveit_resources_panda_description/meshes/r_hand/Link2.STL" />
      </geometry>
      <material
        name="">
        <color
          rgba="0.792156862745098 0.819607843137255 0.933333333333333 1" />
      </material>
    </visual>
    <collision>
      <origin
        xyz="0 0 0"
        rpy="0 0 0" />
      <geometry>
        <mesh
          filename="package://moveit_resources_panda_description/meshes/r_hand/Link2.STL" />
      </geometry>
    </collision>
  </link>
  <joint
    name="panda_finger_joint2"
    type="revolute">
    <origin
      xyz="0.081939 -0.0077547 0.015305"
      rpy="0.0056158 -0.034452 -0.16161" />
    <parent
      link="panda_hand" />
    <child
      link="panda_rightfinger" />
    <axis
      xyz="0 0 1" />
    <limit
      lower="-1.6"
      upper="0"
      effort="1"
      velocity="1" />
  </joint>
  <link
    name="Link22">
    <inertial>
      <origin
        xyz="0.0190179451505274 0.00563447968575673 1.97663586783137E-08"
        rpy="0 0 0" />
      <mass
        value="0.00453367017295165" />
      <inertia
        ixx="8.5696963969299E-08"
        ixy="-3.6550923619766E-08"
        ixz="1.59786933213099E-12"
        iyy="7.58233066456215E-07"
        iyz="6.81108952684927E-13"
        izz="7.68832070821997E-07" />
    </inertial>
    <visual>
      <origin
        xyz="0 0 0"
        rpy="0 0 0" />
      <geometry>
        <mesh
          filename="package://moveit_resources_panda_description/meshes/r_hand/Link22.STL" />
      </geometry>
      <material
        name="">
        <color
          rgba="1 1 1 1" />
      </material>
    </visual>
    <collision>
      <origin
        xyz="0 0 0"
        rpy="0 0 0" />
      <geometry>
        <mesh
          filename="package://moveit_resources_panda_description/meshes/r_hand/Link22.STL" />
      </geometry>
    </collision>
  </link>
  <joint
    name="Link22"
    type="revolute">
    <origin
      xyz="0.032132 0 0"
      rpy="-5.0853E-10 -1.1686E-10 -0.22588" />
    <parent
      link="panda_rightfinger" />
    <child
      link="Link22" />
    <axis
      xyz="0 0 1" />
    <limit
      lower="-1.7"
      upper="0"
      effort="1"
      velocity="1" />
  </joint>
  <link
    name="Link3">
    <inertial>
      <origin
        xyz="0.0107730930654459 0.00213783260244832 -8.57328914740003E-08"
        rpy="0 0 0" />
      <mass
        value="0.0033061482917439" />
      <inertia
        ixx="1.55835970052989E-07"
        ixy="-3.78956285985318E-08"
        ixz="-3.98553229256186E-12"
        iyy="5.30379079243718E-07"
        iyz="-6.32137439938121E-13"
        izz="5.5516012983777E-07" />
    </inertial>
    <visual>
      <origin
        xyz="0 0 0"
        rpy="0 0 0" />
      <geometry>
        <mesh
          filename="package://moveit_resources_panda_description/meshes/r_hand/Link3.STL" />
      </geometry>
      <material
        name="">
        <color
          rgba="0.792156862745098 0.819607843137255 0.933333333333333 1" />
      </material>
    </visual>
    <collision>
      <origin
        xyz="0 0 0"
        rpy="0 0 0" />
      <geometry>
        <mesh
          filename="package://moveit_resources_panda_description/meshes/r_hand/Link3.STL" />
      </geometry>
    </collision>
  </link>
  <joint
    name="Link3"
    type="revolute">
    <origin
      xyz="0.080765 -0.0077547 0.034505"
      rpy="0.010408 -0.086645 -0.11971" />
    <parent
      link="panda_hand" />
    <child
      link="Link3" />
    <axis
      xyz="0 0 1" />
    <limit
      lower="-1.6"
      upper="0"
      effort="1"
      velocity="1" />
  </joint>
  <link
    name="Link33">
    <inertial>
      <origin
        xyz="0.01901789870244 0.00563447090562313 1.70050325960271E-08"
        rpy="0 0 0" />
      <mass
        value="0.00453366652527048" />
      <inertia
        ixx="8.56969335058099E-08"
        ixy="-3.65501984156752E-08"
        ixz="1.30339239962579E-12"
        iyy="7.58232117591424E-07"
        iyz="7.47249892192207E-13"
        izz="7.68830949295352E-07" />
    </inertial>
    <visual>
      <origin
        xyz="0 0 0"
        rpy="0 0 0" />
      <geometry>
        <mesh
          filename="package://moveit_resources_panda_description/meshes/r_hand/Link33.STL" />
      </geometry>
      <material
        name="">
        <color
          rgba="1 1 1 1" />
      </material>
    </visual>
    <collision>
      <origin
        xyz="0 0 0"
        rpy="0 0 0" />
      <geometry>
        <mesh
          filename="package://moveit_resources_panda_description/meshes/r_hand/Link33.STL" />
      </geometry>
    </collision>
  </link>
  <joint
    name="Link33"
    type="revolute">
    <origin
      xyz="0.032132 0 0"
      rpy="-5.0314E-10 -1.3824E-10 -0.26815" />
    <parent
      link="Link3" />
    <child
      link="Link33" />
    <axis
      xyz="0 0 1" />
    <limit
      lower="-1.7"
      upper="0"
      effort="1"
      velocity="1" />
  </joint>
  <link
    name="Link4">
    <inertial>
      <origin
        xyz="0.0107729931213964 0.00213782731321216 -7.95186542376647E-08"
        rpy="0 0 0" />
      <mass
        value="0.00330620800050046" />
      <inertia
        ixx="1.55837389573248E-07"
        ixy="-3.78958987950181E-08"
        ixz="-3.73884747536307E-12"
        iyy="5.30384597648764E-07"
        iyz="-3.63224479792676E-13"
        izz="5.55163794949727E-07" />
    </inertial>
    <visual>
      <origin
        xyz="0 0 0"
        rpy="0 0 0" />
      <geometry>
        <mesh
          filename="package://moveit_resources_panda_description/meshes/r_hand/Link4.STL" />
      </geometry>
      <material
        name="">
        <color
          rgba="0.792156862745098 0.819607843137255 0.933333333333333 1" />
      </material>
    </visual>
    <collision>
      <origin
        xyz="0 0 0"
        rpy="0 0 0" />
      <geometry>
        <mesh
          filename="package://moveit_resources_panda_description/meshes/r_hand/Link4.STL" />
      </geometry>
    </collision>
  </link>
  <joint
    name="Link4"
    type="revolute">
    <origin
      xyz="0.078587 -0.0077547 0.053617"
      rpy="0.022524 -0.13781 -0.16255" />
    <parent
      link="panda_hand" />
    <child
      link="Link4" />
    <axis
      xyz="0 0 1" />
    <limit
      lower="-1.6"
      upper="0"
      effort="1"
      velocity="1" />
  </joint>
  <link
    name="Link44">
    <inertial>
      <origin
        xyz="0.0155924853997512 0.00555619186912998 -1.21775195708468E-07"
        rpy="0 0 0" />
      <mass
        value="0.00356886192445218" />
      <inertia
        ixx="6.67767175628229E-08"
        ixy="-2.70385196277176E-08"
        ixz="-4.60032318294332E-12"
        iyy="4.33416353432936E-07"
        iyz="-1.36538016248102E-12"
        izz="4.39760949009649E-07" />
    </inertial>
    <visual>
      <origin
        xyz="0 0 0"
        rpy="0 0 0" />
      <geometry>
        <mesh
          filename="package://moveit_resources_panda_description/meshes/r_hand/Link44.STL" />
      </geometry>
      <material
        name="">
        <color
          rgba="1 1 1 1" />
      </material>
    </visual>
    <collision>
      <origin
        xyz="0 0 0"
        rpy="0 0 0" />
      <geometry>
        <mesh
          filename="package://moveit_resources_panda_description/meshes/r_hand/Link44.STL" />
      </geometry>
    </collision>
  </link>
  <joint
    name="Link44"
    type="revolute">
    <origin
      xyz="0.032132 0 0"
      rpy="-5.0686E-10 -1.2389E-10 -0.23972" />
    <parent
      link="Link4" />
    <child
      link="Link44" />
    <axis
      xyz="0 0 1" />
    <limit
      lower="-1.7"
      upper="0"
      effort="1"
      velocity="1" />
  </joint>
  <link
    name="Link5">
    <inertial>
      <origin
        xyz="-0.000668287872925624 -0.00209320996353089 0.0037633441647693"
        rpy="0 0 0" />
      <mass
        value="0.00487390663164139" />
      <inertia
        ixx="1.30408513803687E-07"
        ixy="-8.92030281859617E-09"
        ixz="-1.7660325194859E-08"
        iyy="1.70578986810531E-07"
        iyz="-1.02749399337787E-09"
        izz="2.1170907785655E-07" />
    </inertial>
    <visual>
      <origin
        xyz="0 0 0"
        rpy="0 0 0" />
      <geometry>
        <mesh
          filename="package://moveit_resources_panda_description/meshes/r_hand/Link5.STL" />
      </geometry>
      <material
        name="">
        <color
          rgba="0.827450980392157 0.83921568627451 0.827450980392157 1" />
      </material>
    </visual>
    <collision>
      <origin
        xyz="0 0 0"
        rpy="0 0 0" />
      <geometry>
        <mesh
          filename="package://moveit_resources_panda_description/meshes/r_hand/Link5.STL" />
      </geometry>
    </collision>
  </link>
  <joint
    name="Link5"
    type="revolute">
    <origin
      xyz="0.0089225 -0.022949 -0.00699"
      rpy="0.092365 1.1827 -1.4853" />
    <parent
      link="panda_hand" />
    <child
      link="Link5" />
    <axis
      xyz="0 1 0" />
    <limit
      lower="-1"
      upper="0.3"
      effort="1"
      velocity="1" />
  </joint>
  <link
    name="Link51">
    <inertial>
      <origin
        xyz="0.0261732090129406 0.00353701767650547 -1.92601341111875E-07"
        rpy="0 0 0" />
      <mass
        value="0.00652729219675812" />
      <inertia
        ixx="8.93817123585481E-07"
        ixy="6.28368840765271E-08"
        ixz="-2.00458419649248E-11"
        iyy="2.37370603240555E-06"
        iyz="-1.67466441559282E-12"
        izz="2.75021956933668E-06" />
    </inertial>
    <visual>
      <origin
        xyz="0 0 0"
        rpy="0 0 0" />
      <geometry>
        <mesh
          filename="package://moveit_resources_panda_description/meshes/r_hand/Link51.STL" />
      </geometry>
      <material
        name="">
        <color
          rgba="0.792156862745098 0.819607843137255 0.933333333333333 1" />
      </material>
    </visual>
    <collision>
      <origin
        xyz="0 0 0"
        rpy="0 0 0" />
      <geometry>
        <mesh
          filename="package://moveit_resources_panda_description/meshes/r_hand/Link51.STL" />
      </geometry>
    </collision>
  </link>
  <joint
    name="Link51"
    type="revolute">
    <origin
      xyz="0.0065 -0.0035 0.00425"
      rpy="3.1416 -5.2736E-16 0.96726" />
    <parent
      link="Link5" />
    <child
      link="Link51" />
    <axis
      xyz="0 0 -1" />
    <limit
      lower="0"
      upper="0.4"
      effort="1"
      velocity="1" />
  </joint>
  <link
    name="Link52">
    <inertial>
      <origin
        xyz="-0.007316119869056 -0.00552223433089214 2.14610152510231E-07"
        rpy="0 0 0" />
      <mass
        value="0.0022695308360543" />
      <inertia
        ixx="1.7281059843115E-07"
        ixy="4.52282139518593E-08"
        ixz="-2.88816078436063E-12"
        iyy="2.78046552011382E-07"
        iyz="7.05843881266438E-13"
        izz="2.99630657437474E-07" />
    </inertial>
    <visual>
      <origin
        xyz="0 0 0"
        rpy="0 0 0" />
      <geometry>
        <mesh
          filename="package://moveit_resources_panda_description/meshes/r_hand/Link52.STL" />
      </geometry>
      <material
        name="">
        <color
          rgba="0.827450980392157 0.83921568627451 0.827450980392157 1" />
      </material>
    </visual>
    <collision>
      <origin
        xyz="0 0 0"
        rpy="0 0 0" />
      <geometry>
        <mesh
          filename="package://moveit_resources_panda_description/meshes/r_hand/Link52.STL" />
      </geometry>
    </collision>
  </link>
  <joint
    name="Link52"
    type="revolute">
    <origin
      xyz="0.056001 0 0"
      rpy="0 -1.3878E-16 2.9661" />
    <parent
      link="Link51" />
    <child
      link="Link52" />
    <axis
      xyz="0 0 1" />
    <limit
      lower="-0.4"
      upper="0"
      effort="1"
      velocity="1" />
  </joint>
  <link
    name="Link53">
    <inertial>
      <origin
        xyz="-3.3937612879259E-06 0.0106230303829815 0.000584861433263272"
        rpy="0 0 0" />
      <mass
        value="0.00330869751403717" />
      <inertia
        ixx="1.96169236089202E-07"
        ixy="-1.43223823727531E-10"
        ixz="5.64113109591019E-11"
        iyy="8.67914197835909E-08"
        iyz="2.46315104630635E-08"
        izz="1.85481756939709E-07" />
    </inertial>
    <visual>
      <origin
        xyz="0 0 0"
        rpy="0 0 0" />
      <geometry>
        <mesh
          filename="package://moveit_resources_panda_description/meshes/r_hand/Link53.STL" />
      </geometry>
      <material
        name="">
        <color
          rgba="0.827450980392157 0.83921568627451 0.827450980392157 1" />
      </material>
    </visual>
    <collision>
      <origin
        xyz="0 0 0"
        rpy="0 0 0" />
      <geometry>
        <mesh
          filename="package://moveit_resources_panda_description/meshes/r_hand/Link53.STL" />
      </geometry>
    </collision>
  </link>
  <joint
    name="Link53"
    type="revolute">
    <origin
      xyz="-0.022653 0 0"
      rpy="1.7291 -1.5708 0" />
    <parent
      link="Link52" />
    <child
      link="Link53" />
    <axis
      xyz="1 0 0" />
    <limit
      lower="-1"
      upper="0"
      effort="1"
      velocity="1" />
  </joint>





  <link
    name="black_link1">
    <inertial>
      <origin
        xyz="-0.000147330914309851 -0.0467136343507939 -0.085610180554932"
        rpy="0 0 0" />
      <mass
        value="0.154689397372487" />
      <inertia
        ixx="0.000385987070458613"
        ixy="-3.68313317409984E-08"
        ixz="6.21558247648998E-08"
        iyy="0.000411319563174892"
        iyz="-0.000108615353034911"
        izz="0.000169047239167297" />
    </inertial>
    <visual>
      <origin
        xyz="0 0 0"
        rpy="0 0 0" />
      <geometry>
        <mesh
          filename="package://moveit_resources_panda_description/meshes/black_link1.STL" />
      </geometry>
      <material
        name="">
        <color
          rgba="0.792156862745098 0.819607843137255 0.933333333333333 1" />
      </material>
    </visual>
    <collision>
      <origin
        xyz="0 0 0"
        rpy="0 0 0" />
      <geometry>
        <mesh
          filename="package://moveit_resources_panda_description/meshes/black_link1.STL" />
      </geometry>
    </collision>
  </link>
  <joint
    name="black1_joint"
    type="revolute">
    <origin
      xyz="0.133825302830738 0 1.15071708300629"
      rpy="-3.14159265358635 1.30899693899575 0" />
    <parent
      link="panda_link0" />
    <child
      link="black_link1" />
    <axis
      xyz="0 0 1" />
    <limit
      lower="-1.57"
      upper="2.3"
      effort="0"
      velocity="0" />
  </joint>
  <link
    name="black_link2">
    <inertial>
      <origin
        xyz="0.015231 0.063596 0.0050392"
        rpy="0 0 0" />
      <mass
        value="0.15802" />
      <inertia
        ixx="0.00018252"
        ixy="6.617E-06"
        ixz="5.1732E-06"
        iyy="0.00021841"
        iyz="2.4023E-05"
        izz="0.000172" />
    </inertial>
    <visual>
      <origin
        xyz="0 0 0"
        rpy="0 0 0" />
      <geometry>
        <mesh
          filename="package://moveit_resources_panda_description/meshes/black_link2.STL" />
      </geometry>
      <material
        name="">
        <color
          rgba="0.79216 0.81961 0.93333 1" />
      </material>
    </visual>
    <collision>
      <origin
        xyz="0 0 0"
        rpy="0 0 0" />
      <geometry>
        <mesh
          filename="package://moveit_resources_panda_description/meshes/black_link2.STL" />
      </geometry>
    </collision>
  </link>
  <joint
    name="black2_joint"
    type="revolute">
    <origin
      xyz="0 0 -0.116500000000004"
      rpy="1.5707963267949 1.30899693899575 0" />
    <parent
      link="black_link1" />
    <child
      link="black_link2" />
    <axis
      xyz="0 0 1" />
    <limit
      lower="-2.3"
      upper="0.6"
      effort="0"
      velocity="0" />
  </joint>
  <link
    name="black_link3">
    <inertial>
      <origin
        xyz="-0.000194958357011443 -0.00290207053875455 -0.0818858392972155"
        rpy="0 0 0" />
      <mass
        value="0.2616266737403" />
      <inertia
        ixx="0.000234259986142344"
        ixy="2.76038650563224E-07"
        ixz="-1.25293748793433E-07"
        iyy="0.000350258431620994"
        iyz="1.90354364363826E-06"
        izz="0.000180305875713167" />
    </inertial>
    <visual>
      <origin
        xyz="0 0 0"
        rpy="0 0 0" />
      <geometry>
        <mesh
          filename="package://moveit_resources_panda_description/meshes/black_link3.STL" />
      </geometry>
      <material
        name="">
        <color
          rgba="0.792156862745098 0.819607843137255 0.933333333333333 1" />
      </material>
    </visual>
    <collision>
      <origin
        xyz="0 0 0"
        rpy="0 0 0" />
      <geometry>
        <mesh
          filename="package://moveit_resources_panda_description/meshes/black_link3.STL" />
      </geometry>
    </collision>
  </link>
  <joint
    name="black3_joint"
    type="revolute">
    <origin
      xyz="0.0255223354162147 0.111465388775543 0"
      rpy="1.5707963267949 0 -0.22509081564678" />
    <parent
      link="black_link2" />
    <child
      link="black_link3" />
    <axis
      xyz="0 0 -1" />
    <limit
      lower="-2.7"
      upper="0"
      effort="0"
      velocity="0" />
  </joint>
  <link
    name="black_link4">
    <inertial>
      <origin
        xyz="0.010839 0.047684 -0.0052653"
        rpy="0 0 0" />
      <mass
        value="0.14092" />
      <inertia
        ixx="7.3913E-05"
        ixy="1.0077E-06"
        ixz="7.6467E-07"
        iyy="7.9017E-05"
        iyz="3.4449E-06"
        izz="8.108E-05" />
    </inertial>
    <visual>
      <origin
        xyz="0 0 0"
        rpy="0 0 0" />
      <geometry>
        <mesh
          filename="package://moveit_resources_panda_description/meshes/black_link4.STL" />
      </geometry>
      <material
        name="">
        <color
          rgba="0.79216 0.81961 0.93333 1" />
      </material>
    </visual>
    <collision>
      <origin
        xyz="0 0 0"
        rpy="0 0 0" />
      <geometry>
        <mesh
          filename="package://moveit_resources_panda_description/meshes/black_link4.STL" />
      </geometry>
    </collision>
  </link>
  <joint
    name="black4_joint"
    type="revolute">
    <origin
      xyz="0 0 -0.148"
      rpy="-1.57079632679489 0.22509081564678 0" />
    <parent
      link="black_link3" />
    <child
      link="black_link4" />
    <axis
      xyz="0 0 -1" />
    <limit
      lower="-1.8"
      upper="0.0"
      effort="0"
      velocity="0" />
  </joint>
  <link
    name="black_link5">
    <inertial>
      <origin
        xyz="-0.000157689496304125 -0.00394373176326043 -0.0411054710855288"
        rpy="0 0 0" />
      <mass
        value="0.107953940931523" />
      <inertia
        ixx="4.77176378554056E-05"
        ixy="1.32112678235001E-07"
        ixz="-1.27160870445534E-07"
        iyy="7.88480300873772E-05"
        iyz="6.51862983227929E-07"
        izz="5.60287691377555E-05" />
    </inertial>
    <visual>
      <origin
        xyz="0 0 0"
        rpy="0 0 0" />
      <geometry>
        <mesh
          filename="package://moveit_resources_panda_description/meshes/black_link5.STL" />
      </geometry>
      <material
        name="">
        <color
          rgba="0.792156862745098 0.819607843137255 0.933333333333333 1" />
      </material>
    </visual>
    <collision>
      <origin
        xyz="0 0 0"
        rpy="0 0 0" />
      <geometry>
        <mesh
          filename="package://moveit_resources_panda_description/meshes/black_link5.STL" />
      </geometry>
    </collision>
  </link>
  <joint
    name="black5_joint"
    type="revolute">
    <origin
      xyz="0.0240715686458765 0.10512935880584 0"
      rpy="1.57079632679489 0 -0.22509081564678" />
    <parent
      link="black_link4" />
    <child
      link="black_link5" />
    <axis
      xyz="0 0 -1" />
    <limit
      lower="-3.0"
      upper="3.0"
      effort="0"
      velocity="0" />
  </joint>
  <link
    name="black_link6">
    <inertial>
      <origin
        xyz="0.0145488226635636 0.0612682650937144 0.000489624929704972"
        rpy="0 0 0" />
      <mass
        value="0.131069688375068" />
      <inertia
        ixx="0.000105836516770005"
        ixy="-1.00962627236051E-05"
        ixz="2.3064369228159E-06"
        iyy="7.10379062706282E-05"
        iyz="7.82077577834815E-06"
        izz="6.67562209947221E-05" />
    </inertial>
    <visual>
      <origin
        xyz="0 0 0"
        rpy="0 0 0" />
      <geometry>
        <mesh
          filename="package://moveit_resources_panda_description/meshes/black_link6.STL" />
      </geometry>
      <material
        name="">
        <color
          rgba="0.792156862745098 0.819607843137255 0.933333333333333 1" />
      </material>
    </visual>
    <collision>
      <origin
        xyz="0 0 0"
        rpy="0 0 0" />
      <geometry>
        <mesh
          filename="package://moveit_resources_panda_description/meshes/black_link6.STL" />
      </geometry>
    </collision>
  </link>
  <joint
    name="black6_joint"
    type="revolute">
    <origin
      xyz="0 0 -0.0480000000000004"
      rpy="-1.57079632679489 0.22509081564678 0" />
    <parent
      link="black_link5" />
    <child
      link="black_link6" />
    <axis
      xyz="0 0 -1" />
    <limit
      lower="-0.2"
      upper="0.2"
      effort="0"
      velocity="0" />
  </joint>
  <link
    name="black_link7">
    <inertial>
      <origin
        xyz="0.0305863063855117 0.000432529101677278 -0.0265725016997087"
        rpy="0 0 0" />
      <mass
        value="0.025544041765819" />
      <inertia
        ixx="8.43613842809912E-06"
        ixy="-1.63198554595287E-07"
        ixz="1.45208388383198E-06"
        iyy="1.88383743054554E-05"
        iyz="7.8231932308872E-08"
        izz="1.66232633025482E-05" />
    </inertial>
    <visual>
      <origin
        xyz="0 0 0"
        rpy="0 0 0" />
      <geometry>
        <mesh
          filename="package://moveit_resources_panda_description/meshes/black_link7.STL" />
      </geometry>
      <material
        name="">
        <color
          rgba="0.792156862745098 0.819607843137255 0.933333333333333 1" />
      </material>
    </visual>
    <collision>
      <origin
        xyz="0 0 0"
        rpy="0 0 0" />
      <geometry>
        <mesh
          filename="package://moveit_resources_panda_description/meshes/black_link7.STL" />
      </geometry>
    </collision>
  </link>
  <joint
    name="black7_joint"
    type="revolute">
    <origin
      xyz="0.0442154818872393 0.0698945002234028 0.000100000000135983"
      rpy="1.57079632679467 0 1.34570551114812" />
    <parent
      link="black_link6" />
    <child
      link="black_link7" />
    <axis
      xyz="0 0 -1" />
    <limit
      lower="-0.2"
      upper="0.2"
      effort="0"
      velocity="0" />
  </joint>
  <link
    name="neck_link1">
    <inertial>
      <origin
        xyz="0.0128030788061223 0.000219216442743222 0.0319862506332191"
        rpy="0 0 0" />
      <mass
        value="0.239221970649676" />
      <inertia
        ixx="0.000132078127856167"
        ixy="-1.03855244850123E-06"
        ixz="1.61148096438228E-06"
        iyy="0.000192715781288529"
        iyz="2.75920448184419E-08"
        izz="0.0002461205793226" />
    </inertial>
    <visual>
      <origin
        xyz="0 0 0"
        rpy="0 0 0" />
      <geometry>
        <mesh
          filename="package://moveit_resources_panda_description/meshes/neck_link1.STL" />
      </geometry>
      <material
        name="">
        <color
          rgba="0.792156862745098 0.819607843137255 0.933333333333333 1" />
      </material>
    </visual>
    <collision>
      <origin
        xyz="0 0 0"
        rpy="0 0 0" />
      <geometry>
        <mesh
          filename="package://moveit_resources_panda_description/meshes/neck_link1.STL" />
      </geometry>
    </collision>
  </link>
  <joint
    name="neck1_joint"
    type="revolute">
    <origin
      xyz="0 0 1.22674746798424"
      rpy="0 0 0" />
    <parent
      link="panda_link0" />
    <child
      link="neck_link1" />
    <axis
      xyz="0 0 -1" />
    <limit
      lower="-1.57"
      upper="1.57"
      effort="0"
      velocity="0" />
  </joint>
  <link
    name="neck_link2">
    <inertial>
      <origin
        xyz="0.0164380434844709 -0.131873162511601 0.000127334432073337"
        rpy="0 0 0" />
      <mass
        value="1.08294216302997" />
      <inertia
        ixx="0.00463839438456529"
        ixy="-0.000119604564389826"
        ixz="-5.06037342839411E-07"
        iyy="0.00311129988569377"
        iyz="-4.68634735347101E-06"
        izz="0.00427975811281947" />
    </inertial>
    <visual>
      <origin
        xyz="0 0 0"
        rpy="0 0 0" />
      <geometry>
        <mesh
          filename="package://moveit_resources_panda_description/meshes/neck_link2.STL" />
      </geometry>
      <material
        name="">
        <color
          rgba="1 1 1 1" />
      </material>
    </visual>
    <collision>
      <origin
        xyz="0 0 0"
        rpy="0 0 0" />
      <geometry>
        <mesh
          filename="package://moveit_resources_panda_description/meshes/neck_link2.STL" />
      </geometry>
    </collision>
  </link>
  <joint
    name="neck2_joint"
    type="revolute">
    <origin
      xyz="0 0 0.0415000000000025"
      rpy="-1.5707963267949 0 -1.55367583356864" />
    <parent
      link="neck_link1" />
    <child
      link="neck_link2" />
    <axis
      xyz="0 0 -1" />
    <limit
      lower="-0.5"
      upper="0.5"
      effort="0"
      velocity="0" />
  </joint>
  


  <joint name="black_hand" type="fixed">
    <parent link="black_link7"/>
    <child link="BLink111"/>
    <origin rpy="-1.5707963267949 3.14159265358956 1.5707963267949" xyz="0.1 -0.02 -0.02"/>
    <!-- <origin rpy="-1.57 0 0" xyz="0.015 -0.095 -0.01"/> -->
  </joint>

  <link
    name="BLink111">
    <inertial>
      <origin
        xyz="-0.0211971496867713 -0.00980607468332059 -0.0291539210995797"
        rpy="0 0 0" />
      <mass
        value="0.226288892912552" />
      <inertia
        ixx="0.00025807950453196"
        ixy="-4.83159310640912E-06"
        ixz="7.9714751769554E-07"
        iyy="0.000358691949590454"
        iyz="3.73467589382574E-06"
        izz="0.000161017137787831" />
    </inertial>
    <visual>
      <origin
        xyz="0 0 0"
        rpy="0 0 0" />
      <geometry>
        <mesh
          filename="package://moveit_resources_panda_description/meshes/l_hand/Link111.STL" />
      </geometry>
      <material
        name="">
        <color
          rgba="0.827450980392157 0.83921568627451 0.827450980392157 1" />
      </material>
    </visual>
    <collision>
      <origin
        xyz="0 0 0"
        rpy="0 0 0" />
      <geometry>
        <mesh
          filename="package://moveit_resources_panda_description/meshes/l_hand/Link111.STL" />
      </geometry>
    </collision>
  </link>
  <link
    name="BLink1">
    <inertial>
      <origin
        xyz="0.0107728972114067 0.00213787716764519 -1.04416311069722E-07"
        rpy="0 0 0" />
      <mass
        value="0.00330630285835291" />
      <inertia
        ixx="1.55839473420917E-07"
        ixy="-3.78961194376192E-08"
        ixz="-3.77173039190185E-12"
        iyy="5.30393024372046E-07"
        iyz="-7.4062368302925E-13"
        izz="5.55170037339627E-07" />
    </inertial>
    <visual>
      <origin
        xyz="0 0 0"
        rpy="0 0 0" />
      <geometry>
        <mesh
          filename="package://moveit_resources_panda_description/meshes/l_hand/Link1.STL" />
      </geometry>
      <material
        name="">
        <color
          rgba="0.792156862745098 0.819607843137255 0.933333333333333 1" />
      </material>
    </visual>
    <collision>
      <origin
        xyz="0 0 0"
        rpy="0 0 0" />
      <geometry>
        <mesh
          filename="package://moveit_resources_panda_description/meshes/l_hand/Link1.STL" />
      </geometry>
    </collision>
  </link>
  <joint
    name="BLink1"
    type="revolute">
    <origin
      xyz="0.0068852 -0.0077547 -0.08206"
      rpy="-1.4604 1.2485 -1.466" />
    <parent
      link="BLink111" />
    <child
      link="BLink1" />
    <axis
      xyz="0 0 1" />
    <limit
      lower="-1.6"
      upper="0"
      effort="1"
      velocity="1" />
  </joint>
  <link
    name="BLink11">
    <inertial>
      <origin
        xyz="0.0190179143887291 0.00563447080965412 1.42999243835096E-08"
        rpy="0 0 0" />
      <mass
        value="0.00453366979354947" />
      <inertia
        ixx="8.56969401817861E-08"
        ixy="-3.6550236316683E-08"
        ixz="1.43626963228685E-12"
        iyy="7.5823333421962E-07"
        iyz="7.37235171817566E-13"
        izz="7.68832168975162E-07" />
    </inertial>
    <visual>
      <origin
        xyz="0 0 0"
        rpy="0 0 0" />
      <geometry>
        <mesh
          filename="package://moveit_resources_panda_description/meshes/l_hand/Link11.STL" />
      </geometry>
      <material
        name="">
        <color
          rgba="1 1 1 1" />
      </material>
    </visual>
    <collision>
      <origin
        xyz="0 0 0"
        rpy="0 0 0" />
      <geometry>
        <mesh
          filename="package://moveit_resources_panda_description/meshes/l_hand/Link11.STL" />
      </geometry>
    </collision>
  </link>
  <joint
    name="BLink11"
    type="revolute">
    <origin
      xyz="0.032132 0 0"
      rpy="-5.2101E-10 -2.8366E-11 -0.05439" />
    <parent
      link="BLink1" />
    <child
      link="BLink11" />
    <axis
      xyz="0 0 1" />
    <limit
      lower="-1.7"
      upper="0"
      effort="1"
      velocity="1" />
  </joint>
  <link
    name="BLink2">
    <inertial>
      <origin
        xyz="0.0107729848426235 0.00213783905889497 -1.15186638033338E-07"
        rpy="0 0 0" />
      <mass
        value="0.00330621735666597" />
      <inertia
        ixx="1.55837836898236E-07"
        ixy="-3.78957279466946E-08"
        ixz="-4.46779108562076E-12"
        iyy="5.30385092299547E-07"
        iyz="-1.06162548544094E-12"
        izz="5.5516472017082E-07" />
    </inertial>
    <visual>
      <origin
        xyz="0 0 0"
        rpy="0 0 0" />
      <geometry>
        <mesh
          filename="package://moveit_resources_panda_description/meshes/l_hand/Link2.STL" />
      </geometry>
      <material
        name="">
        <color
          rgba="0.792156862745098 0.819607843137255 0.933333333333333 1" />
      </material>
    </visual>
    <collision>
      <origin
        xyz="0 0 0"
        rpy="0 0 0" />
      <geometry>
        <mesh
          filename="package://moveit_resources_panda_description/meshes/l_hand/Link2.STL" />
      </geometry>
    </collision>
  </link>
  <joint
    name="BLink2"
    type="revolute">
    <origin
      xyz="-0.012436 -0.0077547 -0.082423"
      rpy="-1.5708 1.4093 -1.5708" />
    <parent
      link="BLink111" />
    <child
      link="BLink2" />
    <axis
      xyz="0 0 1" />
    <limit
      lower="-1.6"
      upper="0"
      effort="1"
      velocity="1" />
  </joint>
  <link
    name="BLink22">
    <inertial>
      <origin
        xyz="0.0190179449257988 0.00563447974623821 1.95695375043714E-08"
        rpy="0 0 0" />
      <mass
        value="0.00453367027223764" />
      <inertia
        ixx="8.56969657851684E-08"
        ixy="-3.655092334419E-08"
        ixz="1.59947670219807E-12"
        iyy="7.58233058731142E-07"
        iyz="6.82745605693632E-13"
        izz="7.68832058388577E-07" />
    </inertial>
    <visual>
      <origin
        xyz="0 0 0"
        rpy="0 0 0" />
      <geometry>
        <mesh
          filename="package://moveit_resources_panda_description/meshes/l_hand/Link22.STL" />
      </geometry>
      <material
        name="">
        <color
          rgba="1 1 1 1" />
      </material>
    </visual>
    <collision>
      <origin
        xyz="0 0 0"
        rpy="0 0 0" />
      <geometry>
        <mesh
          filename="package://moveit_resources_panda_description/meshes/l_hand/Link22.STL" />
      </geometry>
    </collision>
  </link>
  <joint
    name="BLink22"
    type="revolute">
    <origin
      xyz="0.032132 0 0"
      rpy="-5.0853E-10 -1.1686E-10 -0.22588" />
    <parent
      link="BLink2" />
    <child
      link="BLink22" />
    <axis
      xyz="0 0 1" />
    <limit
      lower="-1.7"
      upper="0"
      effort="1"
      velocity="1" />
  </joint>
  <link
    name="BLink3">
    <inertial>
      <origin
        xyz="0.0107730870011274 0.00213783984115729 -1.4434440405442E-07"
        rpy="0 0 0" />
      <mass
        value="0.00330616517571661" />
      <inertia
        ixx="1.55836709865158E-07"
        ixy="-3.78959914486162E-08"
        ixz="-4.87563626733582E-12"
        iyy="5.30380857158255E-07"
        iyz="-1.32040927550488E-12"
        izz="5.55162479884557E-07" />
    </inertial>
    <visual>
      <origin
        xyz="0 0 0"
        rpy="0 0 0" />
      <geometry>
        <mesh
          filename="package://moveit_resources_panda_description/meshes/l_hand/Link3.STL" />
      </geometry>
      <material
        name="">
        <color
          rgba="0.792156862745098 0.819607843137255 0.933333333333333 1" />
      </material>
    </visual>
    <collision>
      <origin
        xyz="0 0 0"
        rpy="0 0 0" />
      <geometry>
        <mesh
          filename="package://moveit_resources_panda_description/meshes/l_hand/Link3.STL" />
      </geometry>
    </collision>
  </link>
  <joint
    name="BLink3"
    type="revolute">
    <origin
      xyz="-0.031665 -0.0077547 -0.08192"
      rpy="-1.9857 1.4406 -1.9826" />
    <parent
      link="BLink111" />
    <child
      link="BLink3" />
    <axis
      xyz="0 0 1" />
    <limit
      lower="-1.6"
      upper="0"
      effort="1"
      velocity="1" />
  </joint>
  <link
    name="BLink33">
    <inertial>
      <origin
        xyz="0.0190179173374263 0.00563447812355383 2.17778843153438E-08"
        rpy="0 0 0" />
      <mass
        value="0.00453366946672897" />
      <inertia
        ixx="8.56969954123567E-08"
        ixy="-3.65502686172672E-08"
        ixz="1.914131820864E-12"
        iyy="7.58232390943582E-07"
        iyz="6.102905747127E-13"
        izz="7.68831206632801E-07" />
    </inertial>
    <visual>
      <origin
        xyz="0 0 0"
        rpy="0 0 0" />
      <geometry>
        <mesh
          filename="package://moveit_resources_panda_description/meshes/l_hand/Link33.STL" />
      </geometry>
      <material
        name="">
        <color
          rgba="1 1 1 1" />
      </material>
    </visual>
    <collision>
      <origin
        xyz="0 0 0"
        rpy="0 0 0" />
      <geometry>
        <mesh
          filename="package://moveit_resources_panda_description/meshes/l_hand/Link33.STL" />
      </geometry>
    </collision>
  </link>
  <joint
    name="BLink33"
    type="revolute">
    <origin
      xyz="0.032132 0 0"
      rpy="-5.0314E-10 -1.3824E-10 -0.26815" />
    <parent
      link="BLink3" />
    <child
      link="BLink33" />
    <axis
      xyz="0 0 1" />
    <limit
      lower="-1.7"
      upper="0"
      effort="1"
      velocity="1" />
  </joint>
  <link
    name="BLink4">
    <inertial>
      <origin
        xyz="0.0107728838996999 0.00213787812202321 -1.47685512180695E-07"
        rpy="0 0 0" />
      <mass
        value="0.00330630460851054" />
      <inertia
        ixx="1.55839834881808E-07"
        ixy="-3.78966413485388E-08"
        ixz="-5.46215465743034E-12"
        iyy="5.3039377562325E-07"
        iyz="-1.57695349654339E-12"
        izz="5.55171477054147E-07" />
    </inertial>
    <visual>
      <origin
        xyz="0 0 0"
        rpy="0 0 0" />
      <geometry>
        <mesh
          filename="package://moveit_resources_panda_description/meshes/l_hand/Link4.STL" />
      </geometry>
      <material
        name="">
        <color
          rgba="0.792156862745098 0.819607843137255 0.933333333333333 1" />
      </material>
    </visual>
    <collision>
      <origin
        xyz="0 0 0"
        rpy="0 0 0" />
      <geometry>
        <mesh
          filename="package://moveit_resources_panda_description/meshes/l_hand/Link4.STL" />
      </geometry>
    </collision>
  </link>
  <joint
    name="BLink4"
    type="revolute">
    <origin
      xyz="-0.050841 -0.0077547 -0.08041"
      rpy="-2.0186 1.327 -2.007" />
    <parent
      link="BLink111" />
    <child
      link="BLink4" />
    <axis
      xyz="0 0 1" />
    <limit
      lower="-1.6"
      upper="0"
      effort="1"
      velocity="1" />
  </joint>
  <link
    name="BLink44">
    <inertial>
      <origin
        xyz="0.0155924434001128 0.00555617869155978 -1.05483765444614E-07"
        rpy="0 0 0" />
      <mass
        value="0.00356888715893842" />
      <inertia
        ixx="6.67772840408144E-08"
        ixy="-2.70391833548355E-08"
        ixz="-3.26434716125092E-12"
        iyy="4.33419425101179E-07"
        iyz="-9.18888508148905E-13"
        izz="4.39763878420807E-07" />
    </inertial>
    <visual>
      <origin
        xyz="0 0 0"
        rpy="0 0 0" />
      <geometry>
        <mesh
          filename="package://moveit_resources_panda_description/meshes/l_hand/Link44.STL" />
      </geometry>
      <material
        name="">
        <color
          rgba="1 1 1 1" />
      </material>
    </visual>
    <collision>
      <origin
        xyz="0 0 0"
        rpy="0 0 0" />
      <geometry>
        <mesh
          filename="package://moveit_resources_panda_description/meshes/l_hand/Link44.STL" />
      </geometry>
    </collision>
  </link>
  <joint
    name="BLink44"
    type="revolute">
    <origin
      xyz="0.032132 0 0"
      rpy="-5.1334E-10 -9.3483E-11 -0.18013" />
    <parent
      link="BLink4" />
    <child
      link="BLink44" />
    <axis
      xyz="0 0 1" />
    <limit
      lower="-1.7"
      upper="0"
      effort="1"
      velocity="1" />
  </joint>
  <link
    name="BLink5">
    <inertial>
      <origin
        xyz="-0.00433166459951286 0.000656790554769388 -0.000486675184306562"
        rpy="0 0 0" />
      <mass
        value="0.00487393910083768" />
      <inertia
        ixx="1.30409345970056E-07"
        ixy="8.91998160729811E-09"
        ixz="1.76607007575074E-08"
        iyy="1.7058032498292E-07"
        iyz="-1.02771404037179E-09"
        izz="2.11710622768954E-07" />
    </inertial>
    <visual>
      <origin
        xyz="0 0 0"
        rpy="0 0 0" />
      <geometry>
        <mesh
          filename="package://moveit_resources_panda_description/meshes/l_hand/Link5.STL" />
      </geometry>
      <material
        name="">
        <color
          rgba="0.827450980392157 0.83921568627451 0.827450980392157 1" />
      </material>
    </visual>
    <collision>
      <origin
        xyz="0 0 0"
        rpy="0 0 0" />
      <geometry>
        <mesh
          filename="package://moveit_resources_panda_description/meshes/l_hand/Link5.STL" />
      </geometry>
    </collision>
  </link>
  <joint
    name="BLink5"
    type="revolute">
    <origin
      xyz="0.0010638 -0.025 -0.0059231"
      rpy="-1.5708 -2.455E-15 2.3555" />
    <parent
      link="BLink111" />
    <child
      link="BLink5" />
    <axis
      xyz="0 1 0" />
    <limit
      lower="-1"
      upper="0.3"
      effort="1"
      velocity="1" />
  </joint>
  <link
    name="BLink51">
    <inertial>
      <origin
        xyz="0.0261736471642429 0.00353664240332538 -7.35522423800372E-08"
        rpy="0 0 0" />
      <mass
        value="0.00652741708580189" />
      <inertia
        ixx="8.93663478287007E-07"
        ixy="6.28882108303181E-08"
        ixz="-3.67789097092471E-11"
        iyy="2.37350868720489E-06"
        iyz="8.30149702319962E-12"
        izz="2.7502170955408E-06" />
    </inertial>
    <visual>
      <origin
        xyz="0 0 0"
        rpy="0 0 0" />
      <geometry>
        <mesh
          filename="package://moveit_resources_panda_description/meshes/l_hand/Link51.STL" />
      </geometry>
      <material
        name="">
        <color
          rgba="0.792156862745098 0.819607843137255 0.933333333333333 1" />
      </material>
    </visual>
    <collision>
      <origin
        xyz="0 0 0"
        rpy="0 0 0" />
      <geometry>
        <mesh
          filename="package://moveit_resources_panda_description/meshes/l_hand/Link51.STL" />
      </geometry>
    </collision>
  </link>
  <joint
    name="BLink51"
    type="revolute">
    <origin
      xyz="-0.0115 -0.00075 0"
      rpy="-1.4988E-15 -5.5511E-17 1.8988" />
    <parent
      link="BLink5" />
    <child
      link="BLink51" />
    <axis
      xyz="0 0 -1" />
    <limit
      lower="0"
      upper="0.4"
      effort="1"
      velocity="1" />
  </joint>
  <link
    name="BLink52">
    <inertial>
      <origin
        xyz="-0.00731595394729753 -0.00552216810488045 1.31327036717588E-07"
        rpy="0 0 0" />
      <mass
        value="0.00226947954597765" />
      <inertia
        ixx="1.72809908882086E-07"
        ixy="4.52296648937248E-08"
        ixz="-3.78399670014347E-12"
        iyy="2.78044490402836E-07"
        iyz="1.5225345233066E-13"
        izz="2.99628844053565E-07" />
    </inertial>
    <visual>
      <origin
        xyz="0 0 0"
        rpy="0 0 0" />
      <geometry>
        <mesh
          filename="package://moveit_resources_panda_description/meshes/l_hand/Link52.STL" />
      </geometry>
      <material
        name="">
        <color
          rgba="0.827450980392157 0.83921568627451 0.827450980392157 1" />
      </material>
    </visual>
    <collision>
      <origin
        xyz="0 0 0"
        rpy="0 0 0" />
      <geometry>
        <mesh
          filename="package://moveit_resources_panda_description/meshes/l_hand/Link52.STL" />
      </geometry>
    </collision>
  </link>
  <joint
    name="BLink52"
    type="revolute">
    <origin
      xyz="0.056001 0 0"
      rpy="-1.3323E-15 -2.7756E-17 -3.0416" />
    <parent
      link="BLink51" />
    <child
      link="BLink52" />
    <axis
      xyz="0 0 1" />
    <limit
      lower="-0.4"
      upper="0"
      effort="1"
      velocity="1" />
  </joint>
  <link
    name="BLink53">
    <inertial>
      <origin
        xyz="0.0104629360450728 0.00192820283562468 -3.38351464429509E-06"
        rpy="0 0 0" />
      <mass
        value="0.00330869122519449" />
      <inertia
        ixx="8.21794532311926E-08"
        ixy="1.14153196955289E-08"
        ixz="-1.49218673904795E-10"
        iyy="1.90093466236439E-07"
        iyz="3.77060351806357E-11"
        izz="1.96169077984371E-07" />
    </inertial>
    <visual>
      <origin
        xyz="0 0 0"
        rpy="0 0 0" />
      <geometry>
        <mesh
          filename="package://moveit_resources_panda_description/meshes/l_hand/Link53.STL" />
      </geometry>
      <material
        name="">
        <color
          rgba="0.827450980392157 0.83921568627451 0.827450980392157 1" />
      </material>
    </visual>
    <collision>
      <origin
        xyz="0 0 0"
        rpy="0 0 0" />
      <geometry>
        <mesh
          filename="package://moveit_resources_panda_description/meshes/l_hand/Link53.STL" />
      </geometry>
    </collision>
  </link>
  <joint
    name="BLink53"
    type="revolute">
    <origin
      xyz="-0.022653 0 0"
      rpy="1.2712E-14 -9.7145E-17 2.856" />
    <parent
      link="BLink52" />
    <child
      link="BLink53" />
    <axis
      xyz="0 0 1" />
    <limit
      lower="-1"
      upper="0"
      effort="1"
      velocity="1" />
  </joint>


</robot>
